Workbook

Sheet README
A1: MerQuant — BOB Tech Pack Master Data (SKU-level)
A2: Generated 2026-04-20 · 3 source tech packs · 35 SKUs · SKU × fabric-component granularity
A4: COLOR KEY
A5: Dark blue = auto from tech pack (do not edit)
A6: Amber = REQUIRED — fill before import
A7: Yellow = OPTIONAL — fill when data available
A9: SHEETS
A10: 1. Articles (SKUs) — one row per SKU. Fill order_quantity.
A11: 2. SKU Fabric Consumption — one row per SKU × fabric-component. Fill width_cm, consumption_per_unit, wastage_percent.
A12: 3. SKU Accessory Consumption — one row per SKU × label/packaging item. Fill consumption_per_unit.
A13: 4. Carton Master — per-SKU carton dims + CBM (auto).
A14: 5. Price List — per-SKU. Fill price_usd + effective dates.
... A20: per article (SKU), enabling accurate fabric order calculation.

Sheet 1. Articles (SKUs)
A1: tech_pack_code | B1: brand | C1: product_type | D1: size | E1: item_code | F1: bob_sku | G1: color | H1: product_dimensions | I1: insert_dimensions | J1: pvc_bag_dimensions | K1: stiffener_size | L1: units_per_carton | M1: carton_size_cm | N1: order_quantity
A2: FT2 | B2: BOB | C2: Cooling Waterproof mattress protector | D2: TWIN | E2: GPFRIOMP33 | F2: 10001731001 | G2: White | H2: 39X75X14.5” | I2: 26.50x53.00CM | J2: 26.50X26.50+5.00CM | K2: 25.5X26X4.2CM | L2: 10 | M2: 56*29*27
A3: FT2 | B3: BOB | C3: Cooling Waterproof mattress protector | D3: TWIN XL | E3: GPFRIOMP38 | F3: 10001731002 | G3: White | H3: 39X80X15.5” | I3: 26.50x53.00CM | J3: 26.50X26.50+5.00CM | K3: 25.5X26X4.2CM | L3: 10 | M3: 56*29*27
A4: FT2 | B4: BOB | C4: Cooling Waterproof mattress protector | D4: FULL | E4: GPFRIOMP46 | F4: 10001731003 | G4: White | H4: 54X75X14.5” | I4: 26.50x53.00CM | J4: 26.50X26.50+5.00CM | K4: 25.5X26X4.2CM | L4: 10 | M4: 56*29*27
A5: FT2 | B5: BOB | C5: Cooling Waterproof mattress protector | D5: FULL XL | E5: GPFRIOMP80 | G5: White | H5: 54X80X114.5” | I5: 26.50x53.00CM | J5: 26.50X26.50+5.00CM | K5: 25.5X26X4.2CM | L5: 10 | M5: 56*29*27
A6: FT2 | B6: BOB | C6: Cooling Waterproof mattress protector | D6: QUEEN | E6: GPFRIOMP50 | F6: 10001731004 | G6: White | H6: 60X80X17” | I6: 26.50x54.00CM | J6: 26.50X26.50+6.00CM | K6: 25.5X26X5.2CM | L6: 10 | M6: 56*29*32
A7: FT2 | B7: BOB | C7: Cooling Waterproof mattress protector | D7: KING | E7: GPFRIOMP78 | F7: 10001731005 | G7: White | H7: 78X80X17” | I7: 26.50x55.00CM | J7: 26.50X26.50+7.00CM | K7: 25.5X26X6.2CM | L7: 8 | M7: 56*29*30
A8: FT2 | B8: BOB | C8: Cooling Waterproof mattress protector | D8: CAL KING | E8: GPFRIOMP72 | F8: 10001731006 | G8: White | H8: 72x84X17” | I8: 26.50x55.00CM | J8: 26.50X26.50+7.00CM | K8: 25.5X26X6.2CM | L8: 8 | M8: 56*29*30
A9: FT2 | B9: BOB | C9: Cooling Waterproof mattress protector | D9: SPLIT CAL KING | E9: GPFRIOMP36 | G9: White | H9: 36x84X15.5” | I9: 26.50x53.00CM | J9: 26.50X26.50+5.00CM | K9: 25.5X26X4.2CM
A10: FT2 | B10: BOB | C10: Cooling Waterproof mattress protector | D10: SPLIT HEAD QUEEN | E10: GPFRIOMP52 | F10: 10001731008 | G10: White | H10: 60X80X17” | I10: 26.50x54.00CM | J10: 26.50X26.50+6.00CM | K10: 25.5X26X5.2CM | L10: 10 | M10: 56*29*32
A11: FT2 | B11: BOB | C11: Cooling Waterproof mattress protector | D11: SPLIT HEAD KING | E11: GPFRIOMP79 | F11: 10001731009 | G11: White | H11: 76X80X17” | I11: 26.50x55.00CM | J11: 26.50X26.50+7.00CM | K11: 25.5X26X6.2CM | L11: 8 | M11: 56*29*30
A12: FT2 | B12: BOB | C12: Cooling Waterproof mattress protector | D12: QUEEN PILLOW PROTECTOR | E12: GPFRIOPPQ | F12: 10001731010 | G12: White | H12: 21"X31" | I12: 21.00X34.50CM | J12: 23.00X28.00CM | K12: 23.00X28.00CM
A13: FT2 | B13: BOB | C13: Cooling Waterproof mattress protector | D13: KING PILLOW PROTECTOR | E13: GPFRIOPPk | F13: 10001731011 | G13: White | H13: 21"X37" | I13: 21.00X34.50CM | J13: 23.00X28.00CM | K13: 23.00X28.00CM
A14: FT4 | B14: BOB | C14: Poly terry Waterproof mattress protector | D14: TWIN | E14: GPMP33 | G14: White | H14: 39X75X18” | I14: 52.60x27.00CM | J14: 28.00X28.00+5.00CM | K14: 27X27.5X4.2cm
A15: FT4 | B15: BOB | C15: Poly terry Waterproof mattress protector | D15: TWIN XL | E15: GPMP38 | G15: White | H15: 39X80X18” | I15: 52.60x27.00CM | J15: 28.00X28.00+5.00CM | K15: 27X27.5X4.2cm
A16: FT4 | B16: BOB | C16: Poly terry Waterproof mattress protector | D16: FULL | E16: GPMP46 | G16: White | H16: 54X75X18” | I16: 54.60x27.00CM | J16: 28.00X28.00+7.00CM | K16: 27X27.5X6.2cm
A17: FT4 | B17: BOB | C17: Poly terry Waterproof mattress protector | D17: FULL XL | E17: GPMP80 | G17: White | H17: 54X80X18“ | I17: 54.60x27.00CM | J17: 28.00X28.00+7.00CM | K17: 27X27.5X6.2cm
A18: FT4 | B18: BOB | C18: Poly terry Waterproof mattress protector | D18: QUEEN | E18: GPMP50 | G18: White | H18: 60X80X18“ | I18: 54.60x27.00CM | J18: 28.00X28.00+7.00CM | K18: 27X27.5X6.2cm
A19: FT4 | B19: BOB | C19: Poly terry Waterproof mattress protector | D19: KING | E19: GPMP78 | G19: White | H19: 78X80X18“ | I19: 55.60x27.00CM | J19: 28.00X28.00+8.00CM | K19: 27X27.5X7.2cm
A20: FT4 | B20: BOB | C20: Poly terry Waterproof mattress protector | D20: CAL KING | E20: GPMP72 | G20: White | H20: 72x84X18” | I20: 55.70x27.00CM | J20: 28.00X28.00+8.00CM | K20: 27X27.5X6.2cm
A21: FT4 | B21: BOB | C21: Poly terry Waterproof mattress protector | D21: SPLIT CAL KING | E21: GPMP36 | G21: White | H21: 36x84X18” | I21: 52.60x27.00CM | J21: 28.00X28.00+5.00CM | K21: 27X27.5X4.2cm
A22: FT4 | B22: BOB | C22: Poly terry Waterproof mattress protector | D22: SPLIT HEAD QUEEN | E22: GPMP52 | G22: White | H22: 60X80X18“ | I22: 54.60x27.00CM | J22: 28.00X28.00+7.00CM | K22: 27X27.5X6.2cm
A23: FT4 | B23: BOB | C23: Poly terry Waterproof mattress protector | D23: SPLIT HEAD KING | E23: GPMP79 | G23: White | H23: 78X80X18“ | I23: 55.60x27.00CM | J23: 28.00X28.00+8.00CM | K23: 27X27.5X7.2cm
A24: FT9 | B24: BOB | C24: Poly terry waterproof total encasement protector | D24: TWIN | E24: GPTE33 | G24: White | H24: 39x75x11” | I24: 27.00X54.10cm | J24: 28X28X6.5cm | K24: 27X27.5X5.7cm
A25: FT9 | B25: BOB | C25: Poly terry waterproof total encasement protector | D25: TWIN XL | E25: GPTE38 | G25: White | H25: 39x80x11” | I25: 27.00X54.10cm | J25: 28X28X6.5cm | K25: 27X27.5X5.7cm
... A31: FT9 | B31: BOB | C31: Poly terry waterproof total encasement protector | D31: SP CAL KING | E31: GPTE36 | G31: White | H31: 36x84X13.5” | I31: 27.00X54.10cm | J31: 28X28X6.5cm | K31: 27X27.5X5.7cm
A32: FT9 | B32: BOB | C32: Poly terry waterproof total encasement protector | D32: SPLIT HEAD QUEEN | E32: GPTE52 | F32: 10001727013 | G32: White | H32: 60x80x13.5” | I32: 27.00X57.10cm | J32: 28X28X9.5cm | K32: 27X27.5X8.7cm | L32: 10 | M32: 58*28.5*49
A33: FT9 | B33: BOB | C33: Poly terry waterproof total encasement protector | D33: SPLIT HEAD KING | E33: GPTE79 | F33: 10001727007 | G33: White | H33: 78x80x13.5” | I33: 27.00X58.10cm | J33: 28X28X10.5cm | K33: 27X27.5X9.7cm | L33: 8 | M33: 58*28.5*43
A34: FT9 | B34: BOB | C34: Poly terry waterproof total encasement protector | D34: SLEEPER - TWIN | E34: GPSE33 | G34: White | H34: 34x73x5" | I34: 27.00X54.70cm | J34: 28X28X5cm(est) | K34: 27X27.5X4.5cm
A35: FT9 | B35: BOB | C35: Poly terry waterproof total encasement protector | D35: SLEEPER - FULL | E35: GPSE46 | G35: White | H35: 54x73x5” | I35: 27.00X54.70cm | J35: 28X28X7cm | K35: 27X27.5X6.5cm
A36: FT9 | B36: BOB | C36: Poly terry waterproof total encasement protector | D36: SLEEPER - QUEEN | E36: GPSE50 | G36: White | H36: 59x73x5” | I36: 27.00X54.70cm | J36: 28X28X7cm | K36: 27X27.5X6.5cm

Sheet 2. SKU Fabric Consumption
A1: tech_pack_code | B1: item_code | C1: size | D1: component_type | E1: fabric_type | F1: gsm | G1: construction | H1: treatment | I1: color | J1: width_cm | K1: consumption_per_unit | L1: wastage_percent | M1: total_required | N1: supplier
A2: FT2 | B2: GPFRIOMP33 | C2: TWIN | D2: Platform | E2: 140gsm - 100% Nylon mica fiber jersey knitted fabric | F2: 140 | G2: 75D | H2: A) 0.02mmTPU PU Coating in White Color B) SILVADUR (TM) 930 Antimicrobial ‐ PRN 98‐10 | M2: =IFERROR(K2*(1+L2/100)*VLOOKUP(B2,'1. Articles (SKUs)'!E:N,10,FALSE),"")
A3: FT2 | B3: GPFRIOMP33 | C3: TWIN | D3: Skirt | E3: 70gsm - 100% Polyester interlock knitted fabric in white | F3: 70 | G3: 33s | H3: A) 0.02mmTPU PU Coating in White Color B) SILVADUR (TM) 930 Antimicrobial ‐ PRN 98‐10 | I3: White | M3: =IFERROR(K3*(1+L3/100)*VLOOKUP(B3,'1. Articles (SKUs)'!E:N,10,FALSE),"")
A4: FT2 | B4: GPFRIOMP33 | C4: TWIN | D4: Binding | E4: 70gsm - 100% Polyester Plain weave woven fabric in white color | F4: 70 | G4: 190T | I4: White | M4: =IFERROR(K4*(1+L4/100)*VLOOKUP(B4,'1. Articles (SKUs)'!E:N,10,FALSE),"")
A5: FT2 | B5: GPFRIOMP38 | C5: TWIN XL | D5: Platform | E5: 140gsm - 100% Nylon mica fiber jersey knitted fabric | F5: 140 | G5: 75D | H5: A) 0.02mmTPU PU Coating in White Color B) SILVADUR (TM) 930 Antimicrobial ‐ PRN 98‐10 | M5: =IFERROR(K5*(1+L5/100)*VLOOKUP(B5,'1. Articles (SKUs)'!E:N,10,FALSE),"")
A6: FT2 | B6: GPFRIOMP38 | C6: TWIN XL | D6: Skirt | E6: 70gsm - 100% Polyester interlock knitted fabric in white | F6: 70 | G6: 33s | H6: A) 0.02mmTPU PU Coating in White Color B) SILVADUR (TM) 930 Antimicrobial ‐ PRN 98‐10 | I6: White | M6: =IFERROR(K6*(1+L6/100)*VLOOKUP(B6,'1. Articles (SKUs)'!E:N,10,FALSE),"")
A7: FT2 | B7: GPFRIOMP38 | C7: TWIN XL | D7: Binding | E7: 70gsm - 100% Polyester Plain weave woven fabric in white color | F7: 70 | G7: 190T | I7: White | M7: =IFERROR(K7*(1+L7/100)*VLOOKUP(B7,'1. Articles (SKUs)'!E:N,10,FALSE),"")
A8: FT2 | B8: GPFRIOMP46 | C8: FULL | D8: Platform | E8: 140gsm - 100% Nylon mica fiber jersey knitted fabric | F8: 140 | G8: 75D | H8: A) 0.02mmTPU PU Coating in White Color B) SILVADUR (TM) 930 Antimicrobial ‐ PRN 98‐10 | M8: =IFERROR(K8*(1+L8/100)*VLOOKUP(B8,'1. Articles (SKUs)'!E:N,10,FALSE),"")
A9: FT2 | B9: GPFRIOMP46 | C9: FULL | D9: Skirt | E9: 70gsm - 100% Polyester interlock knitted fabric in white | F9: 70 | G9: 33s | H9: A) 0.02mmTPU PU Coating in White Color B) SILVADUR (TM) 930 Antimicrobial ‐ PRN 98‐10 | I9: White | M9: =IFERROR(K9*(1+L9/100)*VLOOKUP(B9,'1. Articles (SKUs)'!E:N,10,FALSE),"")
A10: FT2 | B10: GPFRIOMP46 | C10: FULL | D10: Binding | E10: 70gsm - 100% Polyester Plain weave woven fabric in white color | F10: 70 | G10: 190T | I10: White | M10: =IFERROR(K10*(1+L10/100)*VLOOKUP(B10,'1. Articles (SKUs)'!E:N,10,FALSE),"")
A11: FT2 | B11: GPFRIOMP80 | C11: FULL XL | D11: Platform | E11: 140gsm - 100% Nylon mica fiber jersey knitted fabric | F11: 140 | G11: 75D | H11: A) 0.02mmTPU PU Coating in White Color B) SILVADUR (TM) 930 Antimicrobial ‐ PRN 98‐10 | M11: =IFERROR(K11*(1+L11/100)*VLOOKUP(B11,'1. Articles (SKUs)'!E:N,10,FALSE),"")
A12: FT2 | B12: GPFRIOMP80 | C12: FULL XL | D12: Skirt | E12: 70gsm - 100% Polyester interlock knitted fabric in white | F12: 70 | G12: 33s | H12: A) 0.02mmTPU PU Coating in White Color B) SILVADUR (TM) 930 Antimicrobial ‐ PRN 98‐10 | I12: White | M12: =IFERROR(K12*(1+L12/100)*VLOOKUP(B12,'1. Articles (SKUs)'!E:N,10,FALSE),"")
A13: FT2 | B13: GPFRIOMP80 | C13: FULL XL | D13: Binding | E13: 70gsm - 100% Polyester Plain weave woven fabric in white color | F13: 70 | G13: 190T | I13: White | M13: =IFERROR(K13*(1+L13/100)*VLOOKUP(B13,'1. Articles (SKUs)'!E:N,10,FALSE),"")
A14: FT2 | B14: GPFRIOMP50 | C14: QUEEN | D14: Platform | E14: 140gsm - 100% Nylon mica fiber jersey knitted fabric | F14: 140 | G14: 75D | H14: A) 0.02mmTPU PU Coating in White Color B) SILVADUR (TM) 930 Antimicrobial ‐ PRN 98‐10 | M14: =IFERROR(K14*(1+L14/100)*VLOOKUP(B14,'1. Articles (SKUs)'!E:N,10,FALSE),"")
A15: FT2 | B15: GPFRIOMP50 | C15: QUEEN | D15: Skirt | E15: 70gsm - 100% Polyester interlock knitted fabric in white | F15: 70 | G15: 33s | H15: A) 0.02mmTPU PU Coating in White Color B) SILVADUR (TM) 930 Antimicrobial ‐ PRN 98‐10 | I15: White | M15: =IFERROR(K15*(1+L15/100)*VLOOKUP(B15,'1. Articles (SKUs)'!E:N,10,FALSE),"")
A16: FT2 | B16: GPFRIOMP50 | C16: QUEEN | D16: Binding | E16: 70gsm - 100% Polyester Plain weave woven fabric in white color | F16: 70 | G16: 190T | I16: White | M16: =IFERROR(K16*(1+L16/100)*VLOOKUP(B16,'1. Articles (SKUs)'!E:N,10,FALSE),"")
A17: FT2 | B17: GPFRIOMP78 | C17: KING | D17: Platform | E17: 140gsm - 100% Nylon mica fiber jersey knitted fabric | F17: 140 | G17: 75D | H17: A) 0.02mmTPU PU Coating in White Color B) SILVADUR (TM) 930 Antimicrobial ‐ PRN 98‐10 | M17: =IFERROR(K17*(1+L17/100)*VLOOKUP(B17,'1. Articles (SKUs)'!E:N,10,FALSE),"")
A18: FT2 | B18: GPFRIOMP78 | C18: KING | D18: Skirt | E18: 70gsm - 100% Polyester interlock knitted fabric in white | F18: 70 | G18: 33s | H18: A) 0.02mmTPU PU Coating in White Color B) SILVADUR (TM) 930 Antimicrobial ‐ PRN 98‐10 | I18: White | M18: =IFERROR(K18*(1+L18/100)*VLOOKUP(B18,'1. Articles (SKUs)'!E:N,10,FALSE),"")
A19: FT2 | B19: GPFRIOMP78 | C19: KING | D19: Binding | E19: 70gsm - 100% Polyester Plain weave woven fabric in white color | F19: 70 | G19: 190T | I19: White | M19: =IFERROR(K19*(1+L19/100)*VLOOKUP(B19,'1. Articles (SKUs)'!E:N,10,FALSE),"")
A20: FT2 | B20: GPFRIOMP72 | C20: CAL KING | D20: Platform | E20: 140gsm - 100% Nylon mica fiber jersey knitted fabric | F20: 140 | G20: 75D | H20: A) 0.02mmTPU PU Coating in White Color B) SILVADUR (TM) 930 Antimicrobial ‐ PRN 98‐10 | M20: =IFERROR(K20*(1+L20/100)*VLOOKUP(B20,'1. Articles (SKUs)'!E:N,10,FALSE),"")
A21: FT2 | B21: GPFRIOMP72 | C21: CAL KING | D21: Skirt | E21: 70gsm - 100% Polyester interlock knitted fabric in white | F21: 70 | G21: 33s | H21: A) 0.02mmTPU PU Coating in White Color B) SILVADUR (TM) 930 Antimicrobial ‐ PRN 98‐10 | I21: White | M21: =IFERROR(K21*(1+L21/100)*VLOOKUP(B21,'1. Articles (SKUs)'!E:N,10,FALSE),"")
A22: FT2 | B22: GPFRIOMP72 | C22: CAL KING | D22: Binding | E22: 70gsm - 100% Polyester Plain weave woven fabric in white color | F22: 70 | G22: 190T | I22: White | M22: =IFERROR(K22*(1+L22/100)*VLOOKUP(B22,'1. Articles (SKUs)'!E:N,10,FALSE),"")
A23: FT2 | B23: GPFRIOMP36 | C23: SPLIT CAL KING | D23: Platform | E23: 140gsm - 100% Nylon mica fiber jersey knitted fabric | F23: 140 | G23: 75D | H23: A) 0.02mmTPU PU Coating in White Color B) SILVADUR (TM) 930 Antimicrobial ‐ PRN 98‐10 | M23: =IFERROR(K23*(1+L23/100)*VLOOKUP(B23,'1. Articles (SKUs)'!E:N,10,FALSE),"")
A24: FT2 | B24: GPFRIOMP36 | C24: SPLIT CAL KING | D24: Skirt | E24: 70gsm - 100% Polyester interlock knitted fabric in white | F24: 70 | G24: 33s | H24: A) 0.02mmTPU PU Coating in White Color B) SILVADUR (TM) 930 Antimicrobial ‐ PRN 98‐10 | I24: White | M24: =IFERROR(K24*(1+L24/100)*VLOOKUP(B24,'1. Articles (SKUs)'!E:N,10,FALSE),"")
A25: FT2 | B25: GPFRIOMP36 | C25: SPLIT CAL KING | D25: Binding | E25: 70gsm - 100% Polyester Plain weave woven fabric in white color | F25: 70 | G25: 190T | I25: White | M25: =IFERROR(K25*(1+L25/100)*VLOOKUP(B25,'1. Articles (SKUs)'!E:N,10,FALSE),"")
A26: FT2 | B26: GPFRIOMP52 | C26: SPLIT HEAD QUEEN | D26: Platform | E26: 140gsm - 100% Nylon mica fiber jersey knitted fabric | F26: 140 | G26: 75D | H26: A) 0.02mmTPU PU Coating in White Color B) SILVADUR (TM) 930 Antimicrobial ‐ PRN 98‐10 | M26: =IFERROR(K26*(1+L26/100)*VLOOKUP(B26,'1. Articles (SKUs)'!E:N,10,FALSE),"")
A27: FT2 | B27: GPFRIOMP52 | C27: SPLIT HEAD QUEEN | D27: Skirt | E27: 70gsm - 100% Polyester interlock knitted fabric in white | F27: 70 | G27: 33s | H27: A) 0.02mmTPU PU Coating in White Color B) SILVADUR (TM) 930 Antimicrobial ‐ PRN 98‐10 | I27: White | M27: =IFERROR(K27*(1+L27/100)*VLOOKUP(B27,'1. Articles (SKUs)'!E:N,10,FALSE),"")
A28: FT2 | B28: GPFRIOMP52 | C28: SPLIT HEAD QUEEN | D28: Binding | E28: 70gsm - 100% Polyester Plain weave woven fabric in white color | F28: 70 | G28: 190T | I28: White | M28: =IFERROR(K28*(1+L28/100)*VLOOKUP(B28,'1. Articles (SKUs)'!E:N,10,FALSE),"")
A29: FT2 | B29: GPFRIOMP79 | C29: SPLIT HEAD KING | D29: Platform | E29: 140gsm - 100% Nylon mica fiber jersey knitted fabric | F29: 140 | G29: 75D | H29: A) 0.02mmTPU PU Coating in White Color B) SILVADUR (TM) 930 Antimicrobial ‐ PRN 98‐10 | M29: =IFERROR(K29*(1+L29/100)*VLOOKUP(B29,'1. Articles (SKUs)'!E:N,10,FALSE),"")
A30: FT2 | B30: GPFRIOMP79 | C30: SPLIT HEAD KING | D30: Skirt | E30: 70gsm - 100% Polyester interlock knitted fabric in white | F30: 70 | G30: 33s | H30: A) 0.02mmTPU PU Coating in White Color B) SILVADUR (TM) 930 Antimicrobial ‐ PRN 98‐10 | I30: White | M30: =IFERROR(K30*(1+L30/100)*VLOOKUP(B30,'1. Articles (SKUs)'!E:N,10,FALSE),"")
A31: FT2 | B31: GPFRIOMP79 | C31: SPLIT HEAD KING | D31: Binding | E31: 70gsm - 100% Polyester Plain weave woven fabric in white color | F31: 70 | G31: 190T | I31: White | M31: =IFERROR(K31*(1+L31/100)*VLOOKUP(B31,'1. Articles (SKUs)'!E:N,10,FALSE),"")
A32: FT2 | B32: GPFRIOPPQ | C32: QUEEN PILLOW PROTECTOR | D32: Platform | E32: 140gsm - 100% Nylon mica fiber jersey knitted fabric | F32: 140 | G32: 75D | H32: A) 0.02mmTPU PU Coating in White Color B) SILVADUR (TM) 930 Antimicrobial ‐ PRN 98‐10 | M32: =IFERROR(K32*(1+L32/100)*VLOOKUP(B32,'1. Articles (SKUs)'!E:N,10,FALSE),"")
A33: FT2 | B33: GPFRIOPPQ | C33: QUEEN PILLOW PROTECTOR | D33: Skirt | E33: 70gsm - 100% Polyester interlock knitted fabric in white | F33: 70 | G33: 33s | H33: A) 0.02mmTPU PU Coating in White Color B) SILVADUR (TM) 930 Antimicrobial ‐ PRN 98‐10 | I33: White | M33: =IFERROR(K33*(1+L33/100)*VLOOKUP(B33,'1. Articles (SKUs)'!E:N,10,FALSE),"")
A34: FT2 | B34: GPFRIOPPQ | C34: QUEEN PILLOW PROTECTOR | D34: Binding | E34: 70gsm - 100% Polyester Plain weave woven fabric in white color | F34: 70 | G34: 190T | I34: White | M34: =IFERROR(K34*(1+L34/100)*VLOOKUP(B34,'1. Articles (SKUs)'!E:N,10,FALSE),"")
A35: FT2 | B35: GPFRIOPPk | C35: KING PILLOW PROTECTOR | D35: Platform | E35: 140gsm - 100% Nylon mica fiber jersey knitted fabric | F35: 140 | G35: 75D | H35: A) 0.02mmTPU PU Coating in White Color B) SILVADUR (TM) 930 Antimicrobial ‐ PRN 98‐10 | M35: =IFERROR(K35*(1+L35/100)*VLOOKUP(B35,'1. Articles (SKUs)'!E:N,10,FALSE),"")
A36: FT2 | B36: GPFRIOPPk | C36: KING PILLOW PROTECTOR | D36: Skirt | E36: 70gsm - 100% Polyester interlock knitted fabric in white | F36: 70 | G36: 33s | H36: A) 0.02mmTPU PU Coating in White Color B) SILVADUR (TM) 930 Antimicrobial ‐ PRN 98‐10 | I36: White | M36: =IFERROR(K36*(1+L36/100)*VLOOKUP(B36,'1. Articles (SKUs)'!E:N,10,FALSE),"")
A37: FT2 | B37: GPFRIOPPk | C37: KING PILLOW PROTECTOR | D37: Binding | E37: 70gsm - 100% Polyester Plain weave woven fabric in white color | F37: 70 | G37: 190T | I37: White | M37: =IFERROR(K37*(1+L37/100)*VLOOKUP(B37,'1. Articles (SKUs)'!E:N,10,FALSE),"")
A38: FT4 | B38: GPMP33 | C38: TWIN | D38: Platform | E38: 110gsm - 100% Polyester terry knitted fabric with 0.02mm TPUwhite coating | F38: 110 | G38: 32S Loop / 100D bottom | H38: A) 0.02mmTPU PU Coating in White Color B) SILVADUR (TM) 930 Antimicrobial ‐ PRN 98‐10 C) Wick Away Treatment on Top Platform – TK-N02 | I38: White | M38: =IFERROR(K38*(1+L38/100)*VLOOKUP(B38,'1. Articles (SKUs)'!E:N,10,FALSE),"")
A39: FT4 | B39: GPMP33 | C39: TWIN | D39: Skirt | E39: 100% Polyester mesh knitted fabric | F39: 70 | M39: =IFERROR(K39*(1+L39/100)*VLOOKUP(B39,'1. Articles (SKUs)'!E:N,10,FALSE),"")
A40: FT4 | B40: GPMP33 | C40: TWIN | D40: Piping | E40: Piping fabric - 100% Polyester satin fabric in silver color, Pantone Color - #14-4102TC | F40: 70 | G40: 1/8" thickness | I40: Silver | M40: =IFERROR(K40*(1+L40/100)*VLOOKUP(B40,'1. Articles (SKUs)'!E:N,10,FALSE),"")
...

Sheet 3. SKU Accessory Consumption
A1: tech_pack_code | B1: item_code | C1: size | D1: category | E1: item_name | F1: material | G1: size_spec | H1: placement | I1: consumption_per_unit | J1: wastage_percent | K1: total_required | L1: supplier
A2: FT2 | B2: GPFRIOMP33 | C2: TWIN | D2: Label | E2: Non woven label with coating | F2: 3M non woven material with white ground / black color font (INK CANNOT DISCOLORATION AND STAIN ON PRODUCT) | G2: 9.0cmX13.0cm | H2: Position of law tag label – Sewing at the middle of short side | I2: 1 | J2: 2 | K2: =IFERROR(I2*(1+IFERROR(J2,0)/100)*VLOOKUP(B2,'1. Articles (SKUs)'!E:N,10,FALSE),"")
A3: FT2 | B3: GPFRIOMP33 | C3: TWIN | D3: Label | E3: Non woven label with coating | F3: 3M non woven material with white ground / black color font (INK CANNOT DISCOLORATION AND STAIN ON PRODUCT) | G3: 4.0cmX3.0cm | H3: Position of law tag label for MP & PP – 3" apart from opening (Inside) | I3: 1 | J3: 2 | K3: =IFERROR(I3*(1+IFERROR(J3,0)/100)*VLOOKUP(B3,'1. Articles (SKUs)'!E:N,10,FALSE),"")
A4: FT2 | B4: GPFRIOMP33 | C4: TWIN | D4: Packaging | E4: Packaging type | F4: Color paper insert with vinyl PVC Bag with white bound seam & inside cardboard wrapped by product(Stiffener) | I4: 1 | J4: 2 | K4: =IFERROR(I4*(1+IFERROR(J4,0)/100)*VLOOKUP(B4,'1. Articles (SKUs)'!E:N,10,FALSE),"")
A5: FT2 | B5: GPFRIOMP33 | C5: TWIN | D5: Polybag | E5: Bag material | F5: 12S (Thickness)- Transparent PVC Bag with 7S(Thickness) White PVC White Binding all around seam and 3# Nylon Coil White Zipper(No Hanger Loop on top) | I5: 1 | J5: 2 | K5: =IFERROR(I5*(1+IFERROR(J5,0)/100)*VLOOKUP(B5,'1. Articles (SKUs)'!E:N,10,FALSE),"")
A6: FT2 | B6: GPFRIOMP33 | C6: TWIN | D6: Polybag | E6: Bag material | F6: Size – 3.5cm H X 11.5cm W, 0.35cm (Thickness) - PVC Transparent Polybag with PP Transparent Plastic Hanger on Top, Bag opening at the bottom with automatic adhesive tape.( All PVC Materials need to use NON DEPH Substance to make the bag) | I6: 1 | J6: 2 | K6: =IFERROR(I6*(1+IFERROR(J6,0)/100)*VLOOKUP(B6,'1. Articles (SKUs)'!E:N,10,FALSE),"")
A7: FT2 | B7: GPFRIOMP33 | C7: TWIN | D7: Insert Card | E7: Color paper insert material | F7: Printed Insert quality - INSERT (“U” Shape) - Insert Material: 250g-300g White Card Paper with Coating both side | I7: 1 | J7: 2 | K7: =IFERROR(I7*(1+IFERROR(J7,0)/100)*VLOOKUP(B7,'1. Articles (SKUs)'!E:N,10,FALSE),"")
A8: FT2 | B8: GPFRIOMP33 | C8: TWIN | D8: Insert Card | E8: Color paper insert material | F8: Printed Insert quality - INSERT (“U” Shape) - Insert Material: 250g-300g White Card Paper with Coating both side | I8: 1 | J8: 2 | K8: =IFERROR(I8*(1+IFERROR(J8,0)/100)*VLOOKUP(B8,'1. Articles (SKUs)'!E:N,10,FALSE),"")
A9: FT2 | B9: GPFRIOMP33 | C9: TWIN | D9: Stiffener | E9: Cardboard material(Stiffener) | F9: Packaging inside need to put a “U” 1 ply thickness(1 layers with 1 layer corrugated ) in White Cardboard to maintain the shape before putting into the box | I9: 1 | J9: 2 | K9: =IFERROR(I9*(1+IFERROR(J9,0)/100)*VLOOKUP(B9,'1. Articles (SKUs)'!E:N,10,FALSE),"")
A10: FT2 | B10: GPFRIOMP33 | C10: TWIN | D10: Stiffener | E10: Cardboard material(Stiffener) | F10: White square card | I10: 1 | J10: 2 | K10: =IFERROR(I10*(1+IFERROR(J10,0)/100)*VLOOKUP(B10,'1. Articles (SKUs)'!E:N,10,FALSE),"")
A11: FT2 | B11: GPFRIOMP38 | C11: TWIN XL | D11: Label | E11: Non woven label with coating | F11: 3M non woven material with white ground / black color font (INK CANNOT DISCOLORATION AND STAIN ON PRODUCT) | G11: 9.0cmX13.0cm | H11: Position of law tag label – Sewing at the middle of short side | I11: 1 | J11: 2 | K11: =IFERROR(I11*(1+IFERROR(J11,0)/100)*VLOOKUP(B11,'1. Articles (SKUs)'!E:N,10,FALSE),"")
A12: FT2 | B12: GPFRIOMP38 | C12: TWIN XL | D12: Label | E12: Non woven label with coating | F12: 3M non woven material with white ground / black color font (INK CANNOT DISCOLORATION AND STAIN ON PRODUCT) | G12: 4.0cmX3.0cm | H12: Position of law tag label for MP & PP – 3" apart from opening (Inside) | I12: 1 | J12: 2 | K12: =IFERROR(I12*(1+IFERROR(J12,0)/100)*VLOOKUP(B12,'1. Articles (SKUs)'!E:N,10,FALSE),"")
A13: FT2 | B13: GPFRIOMP38 | C13: TWIN XL | D13: Packaging | E13: Packaging type | F13: Color paper insert with vinyl PVC Bag with white bound seam & inside cardboard wrapped by product(Stiffener) | I13: 1 | J13: 2 | K13: =IFERROR(I13*(1+IFERROR(J13,0)/100)*VLOOKUP(B13,'1. Articles (SKUs)'!E:N,10,FALSE),"")
A14: FT2 | B14: GPFRIOMP38 | C14: TWIN XL | D14: Polybag | E14: Bag material | F14: 12S (Thickness)- Transparent PVC Bag with 7S(Thickness) White PVC White Binding all around seam and 3# Nylon Coil White Zipper(No Hanger Loop on top) | I14: 1 | J14: 2 | K14: =IFERROR(I14*(1+IFERROR(J14,0)/100)*VLOOKUP(B14,'1. Articles (SKUs)'!E:N,10,FALSE),"")
A15: FT2 | B15: GPFRIOMP38 | C15: TWIN XL | D15: Polybag | E15: Bag material | F15: Size – 3.5cm H X 11.5cm W, 0.35cm (Thickness) - PVC Transparent Polybag with PP Transparent Plastic Hanger on Top, Bag opening at the bottom with automatic adhesive tape.( All PVC Materials need to use NON DEPH Substance to make the bag) | I15: 1 | J15: 2 | K15: =IFERROR(I15*(1+IFERROR(J15,0)/100)*VLOOKUP(B15,'1. Articles (SKUs)'!E:N,10,FALSE),"")
A16: FT2 | B16: GPFRIOMP38 | C16: TWIN XL | D16: Insert Card | E16: Color paper insert material | F16: Printed Insert quality - INSERT (“U” Shape) - Insert Material: 250g-300g White Card Paper with Coating both side | I16: 1 | J16: 2 | K16: =IFERROR(I16*(1+IFERROR(J16,0)/100)*VLOOKUP(B16,'1. Articles (SKUs)'!E:N,10,FALSE),"")
A17: FT2 | B17: GPFRIOMP38 | C17: TWIN XL | D17: Insert Card | E17: Color paper insert material | F17: Printed Insert quality - INSERT (“U” Shape) - Insert Material: 250g-300g White Card Paper with Coating both side | I17: 1 | J17: 2 | K17: =IFERROR(I17*(1+IFERROR(J17,0)/100)*VLOOKUP(B17,'1. Articles (SKUs)'!E:N,10,FALSE),"")
A18: FT2 | B18: GPFRIOMP38 | C18: TWIN XL | D18: Stiffener | E18: Cardboard material(Stiffener) | F18: Packaging inside need to put a “U” 1 ply thickness(1 layers with 1 layer corrugated ) in White Cardboard to maintain the shape before putting into the box | I18: 1 | J18: 2 | K18: =IFERROR(I18*(1+IFERROR(J18,0)/100)*VLOOKUP(B18,'1. Articles (SKUs)'!E:N,10,FALSE),"")
A19: FT2 | B19: GPFRIOMP38 | C19: TWIN XL | D19: Stiffener | E19: Cardboard material(Stiffener) | F19: White square card | I19: 1 | J19: 2 | K19: =IFERROR(I19*(1+IFERROR(J19,0)/100)*VLOOKUP(B19,'1. Articles (SKUs)'!E:N,10,FALSE),"")
A20: FT2 | B20: GPFRIOMP46 | C20: FULL | D20: Label | E20: Non woven label with coating | F20: 3M non woven material with white ground / black color font (INK CANNOT DISCOLORATION AND STAIN ON PRODUCT) | G20: 9.0cmX13.0cm | H20: Position of law tag label – Sewing at the middle of short side | I20: 1 | J20: 2 | K20: =IFERROR(I20*(1+IFERROR(J20,0)/100)*VLOOKUP(B20,'1. Articles (SKUs)'!E:N,10,FALSE),"")
A21: FT2 | B21: GPFRIOMP46 | C21: FULL | D21: Label | E21: Non woven label with coating | F21: 3M non woven material with white ground / black color font (INK CANNOT DISCOLORATION AND STAIN ON PRODUCT) | G21: 4.0cmX3.0cm | H21: Position of law tag label for MP & PP – 3" apart from opening (Inside) | I21: 1 | J21: 2 | K21: =IFERROR(I21*(1+IFERROR(J21,0)/100)*VLOOKUP(B21,'1. Articles (SKUs)'!E:N,10,FALSE),"")
A22: FT2 | B22: GPFRIOMP46 | C22: FULL | D22: Packaging | E22: Packaging type | F22: Color paper insert with vinyl PVC Bag with white bound seam & inside cardboard wrapped by product(Stiffener) | I22: 1 | J22: 2 | K22: =IFERROR(I22*(1+IFERROR(J22,0)/100)*VLOOKUP(B22,'1. Articles (SKUs)'!E:N,10,FALSE),"")
A23: FT2 | B23: GPFRIOMP46 | C23: FULL | D23: Polybag | E23: Bag material | F23: 12S (Thickness)- Transparent PVC Bag with 7S(Thickness) White PVC White Binding all around seam and 3# Nylon Coil White Zipper(No Hanger Loop on top) | I23: 1 | J23: 2 | K23: =IFERROR(I23*(1+IFERROR(J23,0)/100)*VLOOKUP(B23,'1. Articles (SKUs)'!E:N,10,FALSE),"")
A24: FT2 | B24: GPFRIOMP46 | C24: FULL | D24: Polybag | E24: Bag material | F24: Size – 3.5cm H X 11.5cm W, 0.35cm (Thickness) - PVC Transparent Polybag with PP Transparent Plastic Hanger on Top, Bag opening at the bottom with automatic adhesive tape.( All PVC Materials need to use NON DEPH Substance to make the bag) | I24: 1 | J24: 2 | K24: =IFERROR(I24*(1+IFERROR(J24,0)/100)*VLOOKUP(B24,'1. Articles (SKUs)'!E:N,10,FALSE),"")
A25: FT2 | B25: GPFRIOMP46 | C25: FULL | D25: Insert Card | E25: Color paper insert material | F25: Printed Insert quality - INSERT (“U” Shape) - Insert Material: 250g-300g White Card Paper with Coating both side | I25: 1 | J25: 2 | K25: =IFERROR(I25*(1+IFERROR(J25,0)/100)*VLOOKUP(B25,'1. Articles (SKUs)'!E:N,10,FALSE),"")
A26: FT2 | B26: GPFRIOMP46 | C26: FULL | D26: Insert Card | E26: Color paper insert material | F26: Printed Insert quality - INSERT (“U” Shape) - Insert Material: 250g-300g White Card Paper with Coating both side | I26: 1 | J26: 2 | K26: =IFERROR(I26*(1+IFERROR(J26,0)/100)*VLOOKUP(B26,'1. Articles (SKUs)'!E:N,10,FALSE),"")
A27: FT2 | B27: GPFRIOMP46 | C27: FULL | D27: Stiffener | E27: Cardboard material(Stiffener) | F27: Packaging inside need to put a “U” 1 ply thickness(1 layers with 1 layer corrugated ) in White Cardboard to maintain the shape before putting into the box | I27: 1 | J27: 2 | K27: =IFERROR(I27*(1+IFERROR(J27,0)/100)*VLOOKUP(B27,'1. Articles (SKUs)'!E:N,10,FALSE),"")
A28: FT2 | B28: GPFRIOMP46 | C28: FULL | D28: Stiffener | E28: Cardboard material(Stiffener) | F28: White square card | I28: 1 | J28: 2 | K28: =IFERROR(I28*(1+IFERROR(J28,0)/100)*VLOOKUP(B28,'1. Articles (SKUs)'!E:N,10,FALSE),"")
A29: FT2 | B29: GPFRIOMP80 | C29: FULL XL | D29: Label | E29: Non woven label with coating | F29: 3M non woven material with white ground / black color font (INK CANNOT DISCOLORATION AND STAIN ON PRODUCT) | G29: 9.0cmX13.0cm | H29: Position of law tag label – Sewing at the middle of short side | I29: 1 | J29: 2 | K29: =IFERROR(I29*(1+IFERROR(J29,0)/100)*VLOOKUP(B29,'1. Articles (SKUs)'!E:N,10,FALSE),"")
A30: FT2 | B30: GPFRIOMP80 | C30: FULL XL | D30: Label | E30: Non woven label with coating | F30: 3M non woven material with white ground / black color font (INK CANNOT DISCOLORATION AND STAIN ON PRODUCT) | G30: 4.0cmX3.0cm | H30: Position of law tag label for MP & PP – 3" apart from opening (Inside) | I30: 1 | J30: 2 | K30: =IFERROR(I30*(1+IFERROR(J30,0)/100)*VLOOKUP(B30,'1. Articles (SKUs)'!E:N,10,FALSE),"")
A31: FT2 | B31: GPFRIOMP80 | C31: FULL XL | D31: Packaging | E31: Packaging type | F31: Color paper insert with vinyl PVC Bag with white bound seam & inside cardboard wrapped by product(Stiffener) | I31: 1 | J31: 2 | K31: =IFERROR(I31*(1+IFERROR(J31,0)/100)*VLOOKUP(B31,'1. Articles (SKUs)'!E:N,10,FALSE),"")
A32: FT2 | B32: GPFRIOMP80 | C32: FULL XL | D32: Polybag | E32: Bag material | F32: 12S (Thickness)- Transparent PVC Bag with 7S(Thickness) White PVC White Binding all around seam and 3# Nylon Coil White Zipper(No Hanger Loop on top) | I32: 1 | J32: 2 | K32: =IFERROR(I32*(1+IFERROR(J32,0)/100)*VLOOKUP(B32,'1. Articles (SKUs)'!E:N,10,FALSE),"")
A33: FT2 | B33: GPFRIOMP80 | C33: FULL XL | D33: Polybag | E33: Bag material | F33: Size – 3.5cm H X 11.5cm W, 0.35cm (Thickness) - PVC Transparent Polybag with PP Transparent Plastic Hanger on Top, Bag opening at the bottom with automatic adhesive tape.( All PVC Materials need to use NON DEPH Substance to make the bag) | I33: 1 | J33: 2 | K33: =IFERROR(I33*(1+IFERROR(J33,0)/100)*VLOOKUP(B33,'1. Articles (SKUs)'!E:N,10,FALSE),"")
A34: FT2 | B34: GPFRIOMP80 | C34: FULL XL | D34: Insert Card | E34: Color paper insert material | F34: Printed Insert quality - INSERT (“U” Shape) - Insert Material: 250g-300g White Card Paper with Coating both side | I34: 1 | J34: 2 | K34: =IFERROR(I34*(1+IFERROR(J34,0)/100)*VLOOKUP(B34,'1. Articles (SKUs)'!E:N,10,FALSE),"")
A35: FT2 | B35: GPFRIOMP80 | C35: FULL XL | D35: Insert Card | E35: Color paper insert material | F35: Printed Insert quality - INSERT (“U” Shape) - Insert Material: 250g-300g White Card Paper with Coating both side | I35: 1 | J35: 2 | K35: =IFERROR(I35*(1+IFERROR(J35,0)/100)*VLOOKUP(B35,'1. Articles (SKUs)'!E:N,10,FALSE),"")
A36: FT2 | B36: GPFRIOMP80 | C36: FULL XL | D36: Stiffener | E36: Cardboard material(Stiffener) | F36: Packaging inside need to put a “U” 1 ply thickness(1 layers with 1 layer corrugated ) in White Cardboard to maintain the shape before putting into the box | I36: 1 | J36: 2 | K36: =IFERROR(I36*(1+IFERROR(J36,0)/100)*VLOOKUP(B36,'1. Articles (SKUs)'!E:N,10,FALSE),"")
A37: FT2 | B37: GPFRIOMP80 | C37: FULL XL | D37: Stiffener | E37: Cardboard material(Stiffener) | F37: White square card | I37: 1 | J37: 2 | K37: =IFERROR(I37*(1+IFERROR(J37,0)/100)*VLOOKUP(B37,'1. Articles (SKUs)'!E:N,10,FALSE),"")
A38: FT2 | B38: GPFRIOMP50 | C38: QUEEN | D38: Label | E38: Non woven label with coating | F38: 3M non woven material with white ground / black color font (INK CANNOT DISCOLORATION AND STAIN ON PRODUCT) | G38: 9.0cmX13.0cm | H38: Position of law tag label – Sewing at the middle of short side | I38: 1 | J38: 2 | K38: =IFERROR(I38*(1+IFERROR(J38,0)/100)*VLOOKUP(B38,'1. Articles (SKUs)'!E:N,10,FALSE),"")
A39: FT2 | B39: GPFRIOMP50 | C39: QUEEN | D39: Label | E39: Non woven label with coating | F39: 3M non woven material with white ground / black color font (INK CANNOT DISCOLORATION AND STAIN ON PRODUCT) | G39: 4.0cmX3.0cm | H39: Position of law tag label for MP & PP – 3" apart from opening (Inside) | I39: 1 | J39: 2 | K39: =IFERROR(I39*(1+IFERROR(J39,0)/100)*VLOOKUP(B39,'1. Articles (SKUs)'!E:N,10,FALSE),"")
A40: FT2 | B40: GPFRIOMP50 | C40: QUEEN | D40: Packaging | E40: Packaging type | F40: Color paper insert with vinyl PVC Bag with white bound seam & inside cardboard wrapped by product(Stiffener) | I40: 1 | J40: 2 | K40: =IFERROR(I40*(1+IFERROR(J40,0)/100)*VLOOKUP(B40,'1. Articles (SKUs)'!E:N,10,FALSE),"")
...

Sheet 4. Carton Master
A1: tech_pack_code | B1: size | C1: item_code | D1: units_per_carton | E1: carton_size_cm | F1: carton_length_cm | G1: carton_width_cm | H1: carton_height_cm | I1: cbm_per_carton | J1: weight_per_carton_kg
A2: FT2 | B2: TWIN | C2: GPFRIOMP33 | D2: 10 | E2: 56*29*27 | F2: 56 | G2: 29 | H2: 27 | I2: 0.0438
A3: FT2 | B3: TWIN XL | C3: GPFRIOMP38 | D3: 10 | E3: 56*29*27 | F3: 56 | G3: 29 | H3: 27 | I3: 0.0438
A4: FT2 | B4: FULL | C4: GPFRIOMP46 | D4: 10 | E4: 56*29*27 | F4: 56 | G4: 29 | H4: 27 | I4: 0.0438
A5: FT2 | B5: FULL XL | C5: GPFRIOMP80 | D5: 10 | E5: 56*29*27 | F5: 56 | G5: 29 | H5: 27 | I5: 0.0438
A6: FT2 | B6: QUEEN | C6: GPFRIOMP50 | D6: 10 | E6: 56*29*32 | F6: 56 | G6: 29 | H6: 32 | I6: 0.052
A7: FT2 | B7: KING | C7: GPFRIOMP78 | D7: 8 | E7: 56*29*30 | F7: 56 | G7: 29 | H7: 30 | I7: 0.0487
A8: FT2 | B8: CAL KING | C8: GPFRIOMP72 | D8: 8 | E8: 56*29*30 | F8: 56 | G8: 29 | H8: 30 | I8: 0.0487
A9: FT2 | B9: SPLIT CAL KING | C9: GPFRIOMP36
A10: FT2 | B10: SPLIT HEAD QUEEN | C10: GPFRIOMP52 | D10: 10 | E10: 56*29*32 | F10: 56 | G10: 29 | H10: 32 | I10: 0.052
A11: FT2 | B11: SPLIT HEAD KING | C11: GPFRIOMP79 | D11: 8 | E11: 56*29*30 | F11: 56 | G11: 29 | H11: 30 | I11: 0.0487
A12: FT2 | B12: QUEEN PILLOW PROTECTOR | C12: GPFRIOPPQ
A13: FT2 | B13: KING PILLOW PROTECTOR | C13: GPFRIOPPk
A14: FT4 | B14: TWIN | C14: GPMP33
A15: FT4 | B15: TWIN XL | C15: GPMP38
A16: FT4 | B16: FULL | C16: GPMP46
A17: FT4 | B17: FULL XL | C17: GPMP80
A18: FT4 | B18: QUEEN | C18: GPMP50
A19: FT4 | B19: KING | C19: GPMP78
A20: FT4 | B20: CAL KING | C20: GPMP72
A21: FT4 | B21: SPLIT CAL KING | C21: GPMP36
A22: FT4 | B22: SPLIT HEAD QUEEN | C22: GPMP52
A23: FT4 | B23: SPLIT HEAD KING | C23: GPMP79
... A31: FT9 | B31: SP CAL KING | C31: GPTE36
A32: FT9 | B32: SPLIT HEAD QUEEN | C32: GPTE52 | D32: 10 | E32: 58*28.5*49 | F32: 58 | G32: 28.5 | H32: 49 | I32: 0.081
A33: FT9 | B33: SPLIT HEAD KING | C33: GPTE79 | D33: 8 | E33: 58*28.5*43 | F33: 58 | G33: 28.5 | H33: 43 | I33: 0.0711
A34: FT9 | B34: SLEEPER - TWIN | C34: GPSE33
A35: FT9 | B35: SLEEPER - FULL | C35: GPSE46
A36: FT9 | B36: SLEEPER - QUEEN | C36: GPSE50

Sheet 5. Price List
A1: item_code | B1: item_description | C1: price_usd | D1: currency | E1: pieces_per_carton | F1: carton_length_cm | G1: carton_width_cm | H1: carton_height_cm | I1: cbm_per_carton | J1: fabric_type | K1: gsm | L1: width_cm | M1: effective_from | N1: effective_to
A2: GPFRIOMP33 | B2: Cooling Waterproof mattress protector — TWIN White | D2: USD | E2: 10 | F2: 56 | G2: 29 | H2: 27 | I2: 0.0438 | J2: 140gsm - 100% Nylon mica fiber jersey knitted fabric | K2: 140
A3: GPFRIOMP38 | B3: Cooling Waterproof mattress protector — TWIN XL White | D3: USD | E3: 10 | F3: 56 | G3: 29 | H3: 27 | I3: 0.0438 | J3: 140gsm - 100% Nylon mica fiber jersey knitted fabric | K3: 140
A4: GPFRIOMP46 | B4: Cooling Waterproof mattress protector — FULL White | D4: USD | E4: 10 | F4: 56 | G4: 29 | H4: 27 | I4: 0.0438 | J4: 140gsm - 100% Nylon mica fiber jersey knitted fabric | K4: 140
A5: GPFRIOMP80 | B5: Cooling Waterproof mattress protector — FULL XL White | D5: USD | E5: 10 | F5: 56 | G5: 29 | H5: 27 | I5: 0.0438 | J5: 140gsm - 100% Nylon mica fiber jersey knitted fabric | K5: 140
A6: GPFRIOMP50 | B6: Cooling Waterproof mattress protector — QUEEN White | D6: USD | E6: 10 | F6: 56 | G6: 29 | H6: 32 | I6: 0.052 | J6: 140gsm - 100% Nylon mica fiber jersey knitted fabric | K6: 140
A7: GPFRIOMP78 | B7: Cooling Waterproof mattress protector — KING White | D7: USD | E7: 8 | F7: 56 | G7: 29 | H7: 30 | I7: 0.0487 | J7: 140gsm - 100% Nylon mica fiber jersey knitted fabric | K7: 140
A8: GPFRIOMP72 | B8: Cooling Waterproof mattress protector — CAL KING White | D8: USD | E8: 8 | F8: 56 | G8: 29 | H8: 30 | I8: 0.0487 | J8: 140gsm - 100% Nylon mica fiber jersey knitted fabric | K8: 140
A9: GPFRIOMP36 | B9: Cooling Waterproof mattress protector — SPLIT CAL KING White | D9: USD | J9: 140gsm - 100% Nylon mica fiber jersey knitted fabric | K9: 140
A10: GPFRIOMP52 | B10: Cooling Waterproof mattress protector — SPLIT HEAD QUEEN White | D10: USD | E10: 10 | F10: 56 | G10: 29 | H10: 32 | I10: 0.052 | J10: 140gsm - 100% Nylon mica fiber jersey knitted fabric | K10: 140
A11: GPFRIOMP79 | B11: Cooling Waterproof mattress protector — SPLIT HEAD KING White | D11: USD | E11: 8 | F11: 56 | G11: 29 | H11: 30 | I11: 0.0487 | J11: 140gsm - 100% Nylon mica fiber jersey knitted fabric | K11: 140
A12: GPFRIOPPQ | B12: Cooling Waterproof mattress protector — QUEEN PILLOW PROTECTOR White | D12: USD | J12: 140gsm - 100% Nylon mica fiber jersey knitted fabric | K12: 140
A13: GPFRIOPPk | B13: Cooling Waterproof mattress protector — KING PILLOW PROTECTOR White | D13: USD | J13: 140gsm - 100% Nylon mica fiber jersey knitted fabric | K13: 140
A14: GPMP33 | B14: Poly terry Waterproof mattress protector — TWIN White | D14: USD | J14: 110gsm - 100% Polyester terry knitted fabric with 0.02mm TPUwhite coating | K14: 110
A15: GPMP38 | B15: Poly terry Waterproof mattress protector — TWIN XL White | D15: USD | J15: 110gsm - 100% Polyester terry knitted fabric with 0.02mm TPUwhite coating | K15: 110
A16: GPMP46 | B16: Poly terry Waterproof mattress protector — FULL White | D16: USD | J16: 110gsm - 100% Polyester terry knitted fabric with 0.02mm TPUwhite coating | K16: 110
A17: GPMP80 | B17: Poly terry Waterproof mattress protector — FULL XL White | D17: USD | J17: 110gsm - 100% Polyester terry knitted fabric with 0.02mm TPUwhite coating | K17: 110
A18: GPMP50 | B18: Poly terry Waterproof mattress protector — QUEEN White | D18: USD | J18: 110gsm - 100% Polyester terry knitted fabric with 0.02mm TPUwhite coating | K18: 110
A19: GPMP78 | B19: Poly terry Waterproof mattress protector — KING White | D19: USD | J19: 110gsm - 100% Polyester terry knitted fabric with 0.02mm TPUwhite coating | K19: 110
A20: GPMP72 | B20: Poly terry Waterproof mattress protector — CAL KING White | D20: USD | J20: 110gsm - 100% Polyester terry knitted fabric with 0.02mm TPUwhite coating | K20: 110
A21: GPMP36 | B21: Poly terry Waterproof mattress protector — SPLIT CAL KING White | D21: USD | J21: 110gsm - 100% Polyester terry knitted fabric with 0.02mm TPUwhite coating | K21: 110
A22: GPMP52 | B22: Poly terry Waterproof mattress protector — SPLIT HEAD QUEEN White | D22: USD | J22: 110gsm - 100% Polyester terry knitted fabric with 0.02mm TPUwhite coating | K22: 110
A23: GPMP79 | B23: Poly terry Waterproof mattress protector — SPLIT HEAD KING White | D23: USD | J23: 110gsm - 100% Polyester terry knitted fabric with 0.02mm TPUwhite coating | K23: 110
... A31: GPTE36 | B31: Poly terry waterproof total encasement protector — SP CAL KING White | D31: USD | J31: 110gsm - 100% Polyester terry knitted fabric with 0.02mm TPUwhite coating | K31: 110
A32: GPTE52 | B32: Poly terry waterproof total encasement protector — SPLIT HEAD QUEEN White | D32: USD | E32: 10 | F32: 58 | G32: 28.5 | H32: 49 | I32: 0.081 | J32: 110gsm - 100% Polyester terry knitted fabric with 0.02mm TPUwhite coating | K32: 110
A33: GPTE79 | B33: Poly terry waterproof total encasement protector — SPLIT HEAD KING White | D33: USD | E33: 8 | F33: 58 | G33: 28.5 | H33: 43 | I33: 0.0711 | J33: 110gsm - 100% Polyester terry knitted fabric with 0.02mm TPUwhite coating | K33: 110
A34: GPSE33 | B34: Poly terry waterproof total encasement protector — SLEEPER - TWIN White | D34: USD | J34: 110gsm - 100% Polyester terry knitted fabric with 0.02mm TPUwhite coating | K34: 110
A35: GPSE46 | B35: Poly terry waterproof total encasement protector — SLEEPER - FULL White | D35: USD | J35: 110gsm - 100% Polyester terry knitted fabric with 0.02mm TPUwhite coating | K35: 110
A36: GPSE50 | B36: Poly terry waterproof total encasement protector — SLEEPER - QUEEN White | D36: USD | J36: 110gsm - 100% Polyester terry knitted fabric with 0.02mm TPUwhite coating | K36: 110
