Workbook

Sheet README
A1: MerQuant — Master Data Sheet v3
A2: Full source of truth: articles, BOM specs, consumption, pricing, carton, suppliers
A4: NEW IN v3
A5: • Product dimensions: product_length_in, product_width_in, product_depth_in (numeric cols)
A6: • Auto-assembled finish_dimensions string (e.g. '39x75x18"')
A7: • Direction column on fabric rows: WXL / LXL / LXW / WXW (inferred by component)
A8: • Rules: Skirt=LXW · Piping+Binding=WXL · Platform+Bottom+Sheet=WXL · Other=user enters
A10: COLOR KEY
A11: Dark blue = auto from BOB tech pack / CSV
A12: Amber = REQUIRED
A13: Yellow = OPTIONAL
A14: Green text = populated with real values
... A28: WXW = Width × Width (small square pieces)

Sheet 1. Articles (SKUs)
A1: tech_pack_code | B1: brand | C1: product_type | D1: product_category | E1: size | F1: item_code | G1: bob_sku | H1: color | I1: product_length_in | J1: product_width_in | K1: product_depth_in | L1: finish_dimensions | M1: insert_dimensions | N1: pvc_bag_dimensions | O1: stiffener_size | P1: zipper_length_cm | Q1: units_per_carton | R1: carton_size_cm
A2: FT2 | B2: BOB | C2: Cooling Waterproof mattress protector | D2: Mattress Protector | E2: TWIN | F2: GPFRIOMP33 | G2: 10001731001 | H2: White | I2: 39 | J2: 75 | K2: 14.5 | L2: 39.0x75.0x14.5" | M2: 26.50x53.00CM | N2: 26.50X26.50+5.00CM | O2: 25.5X26X4.2CM | Q2: 10 | R2: 56*29*27
A3: FT2 | B3: BOB | C3: Cooling Waterproof mattress protector | D3: Mattress Protector | E3: TWIN XL | F3: GPFRIOMP38 | G3: 10001731002 | H3: White | I3: 39 | J3: 80 | K3: 15.5 | L3: 39.0x80.0x15.5" | M3: 26.50x53.00CM | N3: 26.50X26.50+5.00CM | O3: 25.5X26X4.2CM | Q3: 10 | R3: 56*29*27
A4: FT2 | B4: BOB | C4: Cooling Waterproof mattress protector | D4: Mattress Protector | E4: FULL | F4: GPFRIOMP46 | G4: 10001731003 | H4: White | I4: 54 | J4: 75 | K4: 14.5 | L4: 54.0x75.0x14.5" | M4: 26.50x53.00CM | N4: 26.50X26.50+5.00CM | O4: 25.5X26X4.2CM | Q4: 10 | R4: 56*29*27
A5: FT2 | B5: BOB | C5: Cooling Waterproof mattress protector | D5: Mattress Protector | E5: FULL XL | F5: GPFRIOMP80 | H5: White | I5: 54 | J5: 80 | K5: 114.5 | L5: 54.0x80.0x114.5" | M5: 26.50x53.00CM | N5: 26.50X26.50+5.00CM | O5: 25.5X26X4.2CM | Q5: 10 | R5: 56*29*27
A6: FT2 | B6: BOB | C6: Cooling Waterproof mattress protector | D6: Mattress Protector | E6: QUEEN | F6: GPFRIOMP50 | G6: 10001731004 | H6: White | I6: 60 | J6: 80 | K6: 17 | L6: 60.0x80.0x17.0" | M6: 26.50x54.00CM | N6: 26.50X26.50+6.00CM | O6: 25.5X26X5.2CM | Q6: 10 | R6: 56*29*32
A7: FT2 | B7: BOB | C7: Cooling Waterproof mattress protector | D7: Mattress Protector | E7: KING | F7: GPFRIOMP78 | G7: 10001731005 | H7: White | I7: 78 | J7: 80 | K7: 17 | L7: 78.0x80.0x17.0" | M7: 26.50x55.00CM | N7: 26.50X26.50+7.00CM | O7: 25.5X26X6.2CM | Q7: 8 | R7: 56*29*30
A8: FT2 | B8: BOB | C8: Cooling Waterproof mattress protector | D8: Mattress Protector | E8: CAL KING | F8: GPFRIOMP72 | G8: 10001731006 | H8: White | I8: 72 | J8: 84 | K8: 17 | L8: 72.0x84.0x17.0" | M8: 26.50x55.00CM | N8: 26.50X26.50+7.00CM | O8: 25.5X26X6.2CM | Q8: 8 | R8: 56*29*30
A9: FT2 | B9: BOB | C9: Cooling Waterproof mattress protector | D9: Mattress Protector | E9: SPLIT CAL KING | F9: GPFRIOMP36 | H9: White | I9: 36 | J9: 84 | K9: 15.5 | L9: 36.0x84.0x15.5" | M9: 26.50x53.00CM | N9: 26.50X26.50+5.00CM | O9: 25.5X26X4.2CM
A10: FT2 | B10: BOB | C10: Cooling Waterproof mattress protector | D10: Mattress Protector | E10: SPLIT HEAD QUEEN | F10: GPFRIOMP52 | G10: 10001731008 | H10: White | I10: 60 | J10: 80 | K10: 17 | L10: 60.0x80.0x17.0" | M10: 26.50x54.00CM | N10: 26.50X26.50+6.00CM | O10: 25.5X26X5.2CM | Q10: 10 | R10: 56*29*32
A11: FT2 | B11: BOB | C11: Cooling Waterproof mattress protector | D11: Mattress Protector | E11: SPLIT HEAD KING | F11: GPFRIOMP79 | G11: 10001731009 | H11: White | I11: 76 | J11: 80 | K11: 17 | L11: 76.0x80.0x17.0" | M11: 26.50x55.00CM | N11: 26.50X26.50+7.00CM | O11: 25.5X26X6.2CM | Q11: 8 | R11: 56*29*30
A12: FT4 | B12: BOB | C12: Poly terry Waterproof mattress protector | D12: Mattress Protector | E12: TWIN | F12: GPMP33 | H12: White | I12: 39 | J12: 75 | K12: 18 | L12: 39.0x75.0x18.0" | M12: 52.60x27.00CM | N12: 28.00X28.00+5.00CM | O12: 27X27.5X4.2cm
A13: FT4 | B13: BOB | C13: Poly terry Waterproof mattress protector | D13: Mattress Protector | E13: TWIN XL | F13: GPMP38 | H13: White | I13: 39 | J13: 80 | K13: 18 | L13: 39.0x80.0x18.0" | M13: 52.60x27.00CM | N13: 28.00X28.00+5.00CM | O13: 27X27.5X4.2cm
A14: FT4 | B14: BOB | C14: Poly terry Waterproof mattress protector | D14: Mattress Protector | E14: FULL | F14: GPMP46 | H14: White | I14: 54 | J14: 75 | K14: 18 | L14: 54.0x75.0x18.0" | M14: 54.60x27.00CM | N14: 28.00X28.00+7.00CM | O14: 27X27.5X6.2cm
A15: FT4 | B15: BOB | C15: Poly terry Waterproof mattress protector | D15: Mattress Protector | E15: FULL XL | F15: GPMP80 | H15: White | I15: 54 | J15: 80 | K15: 18 | L15: 54.0x80.0x18.0" | M15: 54.60x27.00CM | N15: 28.00X28.00+7.00CM | O15: 27X27.5X6.2cm
A16: FT4 | B16: BOB | C16: Poly terry Waterproof mattress protector | D16: Mattress Protector | E16: QUEEN | F16: GPMP50 | H16: White | I16: 60 | J16: 80 | K16: 18 | L16: 60.0x80.0x18.0" | M16: 54.60x27.00CM | N16: 28.00X28.00+7.00CM | O16: 27X27.5X6.2cm
A17: FT4 | B17: BOB | C17: Poly terry Waterproof mattress protector | D17: Mattress Protector | E17: KING | F17: GPMP78 | H17: White | I17: 78 | J17: 80 | K17: 18 | L17: 78.0x80.0x18.0" | M17: 55.60x27.00CM | N17: 28.00X28.00+8.00CM | O17: 27X27.5X7.2cm
A18: FT4 | B18: BOB | C18: Poly terry Waterproof mattress protector | D18: Mattress Protector | E18: CAL KING | F18: GPMP72 | H18: White | I18: 72 | J18: 84 | K18: 18 | L18: 72.0x84.0x18.0" | M18: 55.70x27.00CM | N18: 28.00X28.00+8.00CM | O18: 27X27.5X6.2cm
A19: FT4 | B19: BOB | C19: Poly terry Waterproof mattress protector | D19: Mattress Protector | E19: SPLIT CAL KING | F19: GPMP36 | H19: White | I19: 36 | J19: 84 | K19: 18 | L19: 36.0x84.0x18.0" | M19: 52.60x27.00CM | N19: 28.00X28.00+5.00CM | O19: 27X27.5X4.2cm
A20: FT4 | B20: BOB | C20: Poly terry Waterproof mattress protector | D20: Mattress Protector | E20: SPLIT HEAD QUEEN | F20: GPMP52 | H20: White | I20: 60 | J20: 80 | K20: 18 | L20: 60.0x80.0x18.0" | M20: 54.60x27.00CM | N20: 28.00X28.00+7.00CM | O20: 27X27.5X6.2cm
A21: FT4 | B21: BOB | C21: Poly terry Waterproof mattress protector | D21: Mattress Protector | E21: SPLIT HEAD KING | F21: GPMP79 | H21: White | I21: 78 | J21: 80 | K21: 18 | L21: 78.0x80.0x18.0" | M21: 55.60x27.00CM | N21: 28.00X28.00+8.00CM | O21: 27X27.5X7.2cm
A22: FT9 | B22: BOB | C22: Poly terry waterproof total encasement protector | D22: Total Encasement | E22: TWIN | F22: GPTE33 | H22: White | I22: 39 | J22: 75 | K22: 11 | L22: 39.0x75.0x11.0" | M22: 27.00X54.10cm | N22: 28X28X6.5cm | O22: 27X27.5X5.7cm | P22: 405
A23: FT9 | B23: BOB | C23: Poly terry waterproof total encasement protector | D23: Total Encasement | E23: TWIN XL | F23: GPTE38 | H23: White | I23: 39 | J23: 80 | K23: 11 | L23: 39.0x80.0x11.0" | M23: 27.00X54.10cm | N23: 28X28X6.5cm | O23: 27X27.5X5.7cm | P23: 430
A24: FT9 | B24: BOB | C24: Poly terry waterproof total encasement protector | D24: Total Encasement | E24: FULL | F24: GPTE46 | H24: White | I24: 54 | J24: 75 | K24: 11 | L24: 54.0x75.0x11.0" | M24: 27.00X56.10cm | N24: 28X28X8.5cm | O24: 27X27.5X7.7cm | P24: 445
A25: FT9 | B25: BOB | C25: Poly terry waterproof total encasement protector | D25: Total Encasement | E25: FULL XL | F25: GPTE80 | H25: White | I25: 54 | J25: 80 | K25: 11 | L25: 54.0x80.0x11.0" | M25: 27.00X56.10cm | N25: 28X28X8.5cm | O25: 27X27.5X7.7cm | P25: 465
A26: FT9 | B26: BOB | C26: Poly terry waterproof total encasement protector | D26: Total Encasement | E26: QUEEN | F26: GPTE50 | H26: White | I26: 60 | J26: 80 | K26: 13.5 | L26: 60.0x80.0x13.5" | M26: 27.00X57.10cm | N26: 28X28X9.5cm | O26: 27X27.5X8.7cm | P26: 482
A27: FT9 | B27: BOB | C27: Poly terry waterproof total encasement protector | D27: Total Encasement | E27: KING | F27: GPTE78 | H27: White | I27: 78 | J27: 80 | K27: 13.5 | L27: 78.0x80.0x13.5" | M27: 27.00X58.10cm | N27: 28X28X10.5cm | O27: 27X27.5X9.7cm | P27: 528
A28: FT9 | B28: BOB | C28: Poly terry waterproof total encasement protector | D28: Total Encasement | E28: CAL KING | F28: GPTE72 | H28: White | I28: 72 | J28: 84 | K28: 13.5 | L28: 72.0x84.0x13.5" | M28: 27.00X58.10cm | N28: 28X28X10.5cm | O28: 27X27.5X9.7cm | P28: 533
A29: FT9 | B29: BOB | C29: Poly terry waterproof total encasement protector | D29: Total Encasement | E29: SP CAL KING | F29: GPTE36 | H29: White | I29: 36 | J29: 84 | K29: 13.5 | L29: 36.0x84.0x13.5" | M29: 27.00X54.10cm | N29: 28X28X6.5cm | O29: 27X27.5X5.7cm | P29: 441
A30: FT9 | B30: BOB | C30: Poly terry waterproof total encasement protector | D30: Total Encasement | E30: SPLIT HEAD QUEEN | F30: GPTE52 | G30: 10001727013 | H30: White | I30: 60 | J30: 80 | K30: 13.5 | L30: 60.0x80.0x13.5" | M30: 27.00X57.10cm | N30: 28X28X9.5cm | O30: 27X27.5X8.7cm | P30: 482 | Q30: 10 | R30: 58*28.5*49
A31: FT9 | B31: BOB | C31: Poly terry waterproof total encasement protector | D31: Total Encasement | E31: SPLIT HEAD KING | F31: GPTE79 | G31: 10001727007 | H31: White | I31: 78 | J31: 80 | K31: 13.5 | L31: 78.0x80.0x13.5" | M31: 27.00X58.10cm | N31: 28X28X10.5cm | O31: 27X27.5X9.7cm | P31: 528 | Q31: 8 | R31: 58*28.5*43
A32: FT9 | B32: BOB | C32: Poly terry waterproof total encasement protector | D32: Sleeper Encasement | E32: SLEEPER - TWIN | F32: GPSE33 | H32: White | I32: 34 | J32: 73 | K32: 5 | L32: 34.0x73.0x5.0" | M32: 27.00X54.70cm | N32: 28X28X5cm(est) | O32: 27X27.5X4.5cm | P32: 405
A33: FT9 | B33: BOB | C33: Poly terry waterproof total encasement protector | D33: Sleeper Encasement | E33: SLEEPER - FULL | F33: GPSE46 | H33: White | I33: 54 | J33: 73 | K33: 5 | L33: 54.0x73.0x5.0" | M33: 27.00X54.70cm | N33: 28X28X7cm | O33: 27X27.5X6.5cm | P33: 445
A34: FT9 | B34: BOB | C34: Poly terry waterproof total encasement protector | D34: Sleeper Encasement | E34: SLEEPER - QUEEN | F34: GPSE50 | H34: White | I34: 59 | J34: 73 | K34: 5 | L34: 59.0x73.0x5.0" | M34: 27.00X54.70cm | N34: 28X28X7cm | O34: 27X27.5X6.5cm | P34: 482
A35: FT4 | B35: Bob's Pillow | C35: Pillow Protector | D35: Pillow Protector | E35: QUEEN | F35: GPPPQ | G35: GPPPQ | H35: White | I35: 31 | J35: 21 | L35: 31x21" | M35: 21cmx34.50cm | N35: 23cmx28cm | O35: 23cmx28cm | P35: 155 | Q35: 24 | R35: 47.0*28.0*25.0
A36: FT4 | B36: Bob's Pillow | C36: Pillow Protector | D36: Pillow Protector | E36: KING | F36: GPPPK | G36: GPPPK | H36: White | I36: 37 | J36: 21 | L36: 37x21" | M36: 21cmx34.50cm | N36: 23cmx28cm | O36: 23cmx28cm | P36: 175 | Q36: 24 | R36: 47.0*28.0*25.0
A37: FT2 | B37: Bob's Pillow | C37: Pillow Protector | D37: Pillow Protector | E37: QUEEN | F37: GPFRIOPPQ | G37: GPFRIOPPQ | H37: White | I37: 31 | J37: 21 | L37: 31x21" | M37: 21cmx34.50cm | N37: 23cmx28cm | O37: 23cmx28cm | P37: 155 | Q37: 24 | R37: 47.0*28.0*25.0
A38: FT2 | B38: Bob's Pillow | C38: Pillow Protector | D38: Pillow Protector | E38: KING | F38: GPFRIOPPK | G38: GPFRIOPPK | H38: White | I38: 37 | J38: 21 | L38: 37x21" | M38: 21cmx34.50cm | N38: 23cmx28cm | O38: 23cmx28cm | P38: 175 | Q38: 24 | R38: 47.0*28.0*25.0

Sheet 2. SKU Fabric Consumption
A1: tech_pack_code | B1: item_code | C1: size | D1: product_size | E1: component_type | F1: direction | G1: fabric_type | H1: construction | I1: yarn_count | J1: composition | K1: gsm | L1: finish | M1: color | N1: width_cm | O1: consumption_per_unit | P1: wastage_percent | Q1: total_required | R1: supplier | S1: remarks
A2: FT2 | B2: GPFRIOMP33 | C2: TWIN | D2: 39.0x75.0x14.5" | E2: Platform | F2: WXL | G2: 140gsm - 100% Nylon mica fiber jersey knitted fabric | J2: Nylon | K2: 140 | L2: A) 0.02mmTPU PU Coating in White Color B) SILVADUR (TM) 930 Antimicrobial ‐ PRN 98‐10 | N2: 200 | O2: 0.98 | P2: 6 | Q2: =IFERROR(O2*(1+P2/100)*VLOOKUP(B2,'1. Articles (SKUs)'!F:R,13,FALSE),"")
A3: FT2 | B3: GPFRIOMP33 | C3: TWIN | D3: 39.0x75.0x14.5" | E3: Skirt | F3: LXW | G3: 70gsm - 100% Polyester interlock knitted fabric in white | J3: 100% Polyester | K3: 70 | L3: Silvadur TM 930 | M3: White | N3: 190 | O3: 1.18 | P3: 6 | Q3: =IFERROR(O3*(1+P3/100)*VLOOKUP(B3,'1. Articles (SKUs)'!F:R,13,FALSE),"")
A4: FT2 | B4: GPFRIOMP33 | C4: TWIN | D4: 39.0x75.0x14.5" | E4: Binding | F4: WXL | G4: 70gsm - 100% Polyester Plain weave woven fabric in white color | J4: 100% Polyester | K4: 70 | M4: White | N4: 180 | O4: 0.13 | P4: 6 | Q4: =IFERROR(O4*(1+P4/100)*VLOOKUP(B4,'1. Articles (SKUs)'!F:R,13,FALSE),"")
A5: FT2 | B5: GPFRIOMP38 | C5: TWIN XL | D5: 39.0x80.0x15.5" | E5: Platform | F5: WXL | G5: 140gsm - 100% Nylon mica fiber jersey knitted fabric | J5: Nylon | K5: 140 | L5: A) 0.02mmTPU PU Coating in White Color B) SILVADUR (TM) 930 Antimicrobial ‐ PRN 98‐10 | N5: 200 | O5: 1.04 | P5: 6 | Q5: =IFERROR(O5*(1+P5/100)*VLOOKUP(B5,'1. Articles (SKUs)'!F:R,13,FALSE),"")
A6: FT2 | B6: GPFRIOMP38 | C6: TWIN XL | D6: 39.0x80.0x15.5" | E6: Skirt | F6: LXW | G6: 70gsm - 100% Polyester interlock knitted fabric in white | J6: 100% Polyester | K6: 70 | L6: Silvadur TM 930 | M6: White | N6: 190 | O6: 1.23 | P6: 6 | Q6: =IFERROR(O6*(1+P6/100)*VLOOKUP(B6,'1. Articles (SKUs)'!F:R,13,FALSE),"")
A7: FT2 | B7: GPFRIOMP38 | C7: TWIN XL | D7: 39.0x80.0x15.5" | E7: Binding | F7: WXL | G7: 70gsm - 100% Polyester Plain weave woven fabric in white color | J7: 100% Polyester | K7: 70 | M7: White | N7: 180 | O7: 0.14 | P7: 6 | Q7: =IFERROR(O7*(1+P7/100)*VLOOKUP(B7,'1. Articles (SKUs)'!F:R,13,FALSE),"")
A8: FT2 | B8: GPFRIOMP46 | C8: FULL | D8: 54.0x75.0x14.5" | E8: Platform | F8: WXL | G8: 140gsm - 100% Nylon mica fiber jersey knitted fabric | J8: Nylon | K8: 140 | L8: A) 0.02mmTPU PU Coating in White Color B) SILVADUR (TM) 930 Antimicrobial ‐ PRN 98‐10 | N8: 200 | O8: 1.42 | P8: 6 | Q8: =IFERROR(O8*(1+P8/100)*VLOOKUP(B8,'1. Articles (SKUs)'!F:R,13,FALSE),"")
A9: FT2 | B9: GPFRIOMP46 | C9: FULL | D9: 54.0x75.0x14.5" | E9: Skirt | F9: LXW | G9: 70gsm - 100% Polyester interlock knitted fabric in white | J9: 100% Polyester | K9: 70 | L9: Silvadur TM 930 | M9: White | N9: 190 | O9: 1.33 | P9: 6 | Q9: =IFERROR(O9*(1+P9/100)*VLOOKUP(B9,'1. Articles (SKUs)'!F:R,13,FALSE),"")
A10: FT2 | B10: GPFRIOMP46 | C10: FULL | D10: 54.0x75.0x14.5" | E10: Binding | F10: WXL | G10: 70gsm - 100% Polyester Plain weave woven fabric in white color | J10: 100% Polyester | K10: 70 | M10: White | N10: 180 | O10: 0.15 | P10: 6 | Q10: =IFERROR(O10*(1+P10/100)*VLOOKUP(B10,'1. Articles (SKUs)'!F:R,13,FALSE),"")
A11: FT2 | B11: GPFRIOMP80 | C11: FULL XL | D11: 54.0x80.0x114.5" | E11: Platform | F11: WXL | G11: 140gsm - 100% Nylon mica fiber jersey knitted fabric | J11: Nylon | K11: 140 | L11: A) 0.02mmTPU PU Coating in White Color B) SILVADUR (TM) 930 Antimicrobial ‐ PRN 98‐10 | N11: 200 | O11: 1.09 | P11: 6 | Q11: =IFERROR(O11*(1+P11/100)*VLOOKUP(B11,'1. Articles (SKUs)'!F:R,13,FALSE),"")
A12: FT2 | B12: GPFRIOMP80 | C12: FULL XL | D12: 54.0x80.0x114.5" | E12: Skirt | F12: LXW | G12: 70gsm - 100% Polyester interlock knitted fabric in white | J12: 100% Polyester | K12: 70 | L12: Silvadur TM 930 | M12: White | N12: 190 | O12: 1.24 | P12: 6 | Q12: =IFERROR(O12*(1+P12/100)*VLOOKUP(B12,'1. Articles (SKUs)'!F:R,13,FALSE),"")
A13: FT2 | B13: GPFRIOMP80 | C13: FULL XL | D13: 54.0x80.0x114.5" | E13: Binding | F13: WXL | G13: 70gsm - 100% Polyester Plain weave woven fabric in white color | J13: 100% Polyester | K13: 70 | M13: White | N13: 180 | O13: 0.14 | P13: 6 | Q13: =IFERROR(O13*(1+P13/100)*VLOOKUP(B13,'1. Articles (SKUs)'!F:R,13,FALSE),"")
A14: FT2 | B14: GPFRIOMP50 | C14: QUEEN | D14: 60.0x80.0x17.0" | E14: Platform | F14: WXL | G14: 140gsm - 100% Nylon mica fiber jersey knitted fabric | J14: Nylon | K14: 140 | L14: A) 0.02mmTPU PU Coating in White Color B) SILVADUR (TM) 930 Antimicrobial ‐ PRN 98‐10 | N14: 200 | O14: 1.57 | P14: 6 | Q14: =IFERROR(O14*(1+P14/100)*VLOOKUP(B14,'1. Articles (SKUs)'!F:R,13,FALSE),"")
A15: FT2 | B15: GPFRIOMP50 | C15: QUEEN | D15: 60.0x80.0x17.0" | E15: Skirt | F15: LXW | G15: 70gsm - 100% Polyester interlock knitted fabric in white | J15: 100% Polyester | K15: 70 | L15: Silvadur TM 930 | M15: White | N15: 190 | O15: 1.8 | P15: 6 | Q15: =IFERROR(O15*(1+P15/100)*VLOOKUP(B15,'1. Articles (SKUs)'!F:R,13,FALSE),"")
A16: FT2 | B16: GPFRIOMP50 | C16: QUEEN | D16: 60.0x80.0x17.0" | E16: Binding | F16: WXL | G16: 70gsm - 100% Polyester Plain weave woven fabric in white color | J16: 100% Polyester | K16: 70 | M16: White | N16: 180 | O16: 0.16 | P16: 6 | Q16: =IFERROR(O16*(1+P16/100)*VLOOKUP(B16,'1. Articles (SKUs)'!F:R,13,FALSE),"")
A17: FT2 | B17: GPFRIOMP78 | C17: KING | D17: 78.0x80.0x17.0" | E17: Platform | F17: WXL | G17: 140gsm - 100% Nylon mica fiber jersey knitted fabric | J17: Nylon | K17: 140 | L17: A) 0.02mmTPU PU Coating in White Color B) SILVADUR (TM) 930 Antimicrobial ‐ PRN 98‐10 | N17: 200 | O17: 2.03 | P17: 6 | Q17: =IFERROR(O17*(1+P17/100)*VLOOKUP(B17,'1. Articles (SKUs)'!F:R,13,FALSE),"")
A18: FT2 | B18: GPFRIOMP78 | C18: KING | D18: 78.0x80.0x17.0" | E18: Skirt | F18: LXW | G18: 70gsm - 100% Polyester interlock knitted fabric in white | J18: 100% Polyester | K18: 70 | L18: Silvadur TM 930 | M18: White | N18: 190 | O18: 2.03 | P18: 6 | Q18: =IFERROR(O18*(1+P18/100)*VLOOKUP(B18,'1. Articles (SKUs)'!F:R,13,FALSE),"")
A19: FT2 | B19: GPFRIOMP78 | C19: KING | D19: 78.0x80.0x17.0" | E19: Binding | F19: WXL | G19: 70gsm - 100% Polyester Plain weave woven fabric in white color | J19: 100% Polyester | K19: 70 | M19: White | N19: 180 | O19: 0.18 | P19: 6 | Q19: =IFERROR(O19*(1+P19/100)*VLOOKUP(B19,'1. Articles (SKUs)'!F:R,13,FALSE),"")
A20: FT2 | B20: GPFRIOMP72 | C20: CAL KING | D20: 72.0x84.0x17.0" | E20: Platform | F20: WXL | G20: 140gsm - 100% Nylon mica fiber jersey knitted fabric | J20: Nylon | K20: 140 | L20: A) 0.02mmTPU PU Coating in White Color B) SILVADUR (TM) 930 Antimicrobial ‐ PRN 98‐10 | N20: 200 | O20: 2.18 | P20: 6 | Q20: =IFERROR(O20*(1+P20/100)*VLOOKUP(B20,'1. Articles (SKUs)'!F:R,13,FALSE),"")
A21: FT2 | B21: GPFRIOMP72 | C21: CAL KING | D21: 72.0x84.0x17.0" | E21: Skirt | F21: LXW | G21: 70gsm - 100% Polyester interlock knitted fabric in white | J21: 100% Polyester | K21: 70 | L21: Silvadur TM 930 | M21: White | N21: 190 | O21: 2.01 | P21: 6 | Q21: =IFERROR(O21*(1+P21/100)*VLOOKUP(B21,'1. Articles (SKUs)'!F:R,13,FALSE),"")
A22: FT2 | B22: GPFRIOMP72 | C22: CAL KING | D22: 72.0x84.0x17.0" | E22: Binding | F22: WXL | G22: 70gsm - 100% Polyester Plain weave woven fabric in white color | J22: 100% Polyester | K22: 70 | M22: White | N22: 180 | O22: 0.18 | P22: 6 | Q22: =IFERROR(O22*(1+P22/100)*VLOOKUP(B22,'1. Articles (SKUs)'!F:R,13,FALSE),"")
A23: FT2 | B23: GPFRIOMP36 | C23: SPLIT CAL KING | D23: 36.0x84.0x15.5" | E23: Platform | F23: WXL | G23: 140gsm - 100% Nylon mica fiber jersey knitted fabric | K23: 140 | L23: A) 0.02mmTPU PU Coating in White Color B) SILVADUR (TM) 930 Antimicrobial ‐ PRN 98‐10 | Q23: =IFERROR(O23*(1+P23/100)*VLOOKUP(B23,'1. Articles (SKUs)'!F:R,13,FALSE),"")
A24: FT2 | B24: GPFRIOMP36 | C24: SPLIT CAL KING | D24: 36.0x84.0x15.5" | E24: Skirt | F24: LXW | G24: 70gsm - 100% Polyester interlock knitted fabric in white | K24: 70 | L24: A) 0.02mmTPU PU Coating in White Color B) SILVADUR (TM) 930 Antimicrobial ‐ PRN 98‐10 | M24: White | Q24: =IFERROR(O24*(1+P24/100)*VLOOKUP(B24,'1. Articles (SKUs)'!F:R,13,FALSE),"")
A25: FT2 | B25: GPFRIOMP36 | C25: SPLIT CAL KING | D25: 36.0x84.0x15.5" | E25: Binding | F25: WXL | G25: 70gsm - 100% Polyester Plain weave woven fabric in white color | K25: 70 | M25: White | Q25: =IFERROR(O25*(1+P25/100)*VLOOKUP(B25,'1. Articles (SKUs)'!F:R,13,FALSE),"")
A26: FT2 | B26: GPFRIOMP52 | C26: SPLIT HEAD QUEEN | D26: 60.0x80.0x17.0" | E26: Platform | F26: WXL | G26: 140gsm - 100% Nylon mica fiber jersey knitted fabric | J26: Nylon | K26: 140 | L26: A) 0.02mmTPU PU Coating in White Color B) SILVADUR (TM) 930 Antimicrobial ‐ PRN 98‐10 | N26: 200 | O26: 1.63 | P26: 6 | Q26: =IFERROR(O26*(1+P26/100)*VLOOKUP(B26,'1. Articles (SKUs)'!F:R,13,FALSE),"")
A27: FT2 | B27: GPFRIOMP52 | C27: SPLIT HEAD QUEEN | D27: 60.0x80.0x17.0" | E27: Skirt | F27: LXW | G27: 70gsm - 100% Polyester interlock knitted fabric in white | J27: 100% Polyester | K27: 70 | L27: Silvadur TM 930 | M27: White | N27: 190 | O27: 2.25 | P27: 6 | Q27: =IFERROR(O27*(1+P27/100)*VLOOKUP(B27,'1. Articles (SKUs)'!F:R,13,FALSE),"")
A28: FT2 | B28: GPFRIOMP52 | C28: SPLIT HEAD QUEEN | D28: 60.0x80.0x17.0" | E28: Binding | F28: WXL | G28: 70gsm - 100% Polyester Plain weave woven fabric in white color | J28: 100% Polyester | K28: 70 | M28: White | N28: 180 | O28: 0.21 | P28: 6 | Q28: =IFERROR(O28*(1+P28/100)*VLOOKUP(B28,'1. Articles (SKUs)'!F:R,13,FALSE),"")
A29: FT2 | B29: GPFRIOMP79 | C29: SPLIT HEAD KING | D29: 76.0x80.0x17.0" | E29: Platform | F29: WXL | G29: 140gsm - 100% Nylon mica fiber jersey knitted fabric | J29: Nylon | K29: 140 | L29: A) 0.02mmTPU PU Coating in White Color B) SILVADUR (TM) 930 Antimicrobial ‐ PRN 98‐10 | N29: 200 | O29: 2.08 | P29: 6 | Q29: =IFERROR(O29*(1+P29/100)*VLOOKUP(B29,'1. Articles (SKUs)'!F:R,13,FALSE),"")
A30: FT2 | B30: GPFRIOMP79 | C30: SPLIT HEAD KING | D30: 76.0x80.0x17.0" | E30: Skirt | F30: LXW | G30: 70gsm - 100% Polyester interlock knitted fabric in white | J30: 100% Polyester | K30: 70 | L30: Silvadur TM 930 | M30: White | N30: 190 | O30: 2.48 | P30: 6 | Q30: =IFERROR(O30*(1+P30/100)*VLOOKUP(B30,'1. Articles (SKUs)'!F:R,13,FALSE),"")
A31: FT2 | B31: GPFRIOMP79 | C31: SPLIT HEAD KING | D31: 76.0x80.0x17.0" | E31: Binding | F31: WXL | G31: 70gsm - 100% Polyester Plain weave woven fabric in white color | J31: 100% Polyester | K31: 70 | M31: White | N31: 180 | O31: 0.23 | P31: 6 | Q31: =IFERROR(O31*(1+P31/100)*VLOOKUP(B31,'1. Articles (SKUs)'!F:R,13,FALSE),"")
A32: FT4 | B32: GPMP33 | C32: TWIN | D32: 39.0x75.0x18.0" | E32: Platform | F32: WXL | G32: 110gsm - 100% Polyester terry knitted fabric with 0.02mm TPUwhite coating | J32: 100% Polyester | K32: 110 | L32: TPU coated | M32: White | N32: 208 | O32: 0.98 | P32: 6 | Q32: =IFERROR(O32*(1+P32/100)*VLOOKUP(B32,'1. Articles (SKUs)'!F:R,13,FALSE),"")
A33: FT4 | B33: GPMP33 | C33: TWIN | D33: 39.0x75.0x18.0" | E33: Skirt | F33: LXW | G33: 100% Polyester mesh knitted fabric | J33: 100% Polyester | K33: 70 | N33: 190 | O33: 1.47 | P33: 6 | Q33: =IFERROR(O33*(1+P33/100)*VLOOKUP(B33,'1. Articles (SKUs)'!F:R,13,FALSE),"")
A34: FT4 | B34: GPMP33 | C34: TWIN | D34: 39.0x75.0x18.0" | E34: Piping | F34: WXL | G34: Piping fabric - 100% Polyester satin fabric in silver color, Pantone Color - #14-4102TC | J34: 100% Polyester | K34: 70 | M34: Silver | N34: 180 | O34: 0.19 | P34: 6 | Q34: =IFERROR(O34*(1+P34/100)*VLOOKUP(B34,'1. Articles (SKUs)'!F:R,13,FALSE),"")
A35: FT4 | B35: GPMP38 | C35: TWIN XL | D35: 39.0x80.0x18.0" | E35: Platform | F35: WXL | G35: 110gsm - 100% Polyester terry knitted fabric with 0.02mm TPUwhite coating | J35: 100% Polyester | K35: 110 | L35: TPU coated | M35: White | N35: 208 | O35: 1.04 | P35: 6 | Q35: =IFERROR(O35*(1+P35/100)*VLOOKUP(B35,'1. Articles (SKUs)'!F:R,13,FALSE),"")
A36: FT4 | B36: GPMP38 | C36: TWIN XL | D36: 39.0x80.0x18.0" | E36: Skirt | F36: LXW | G36: 100% Polyester mesh knitted fabric | J36: 100% Polyester | K36: 70 | N36: 190 | O36: 1.54 | P36: 6 | Q36: =IFERROR(O36*(1+P36/100)*VLOOKUP(B36,'1. Articles (SKUs)'!F:R,13,FALSE),"")
A37: FT4 | B37: GPMP38 | C37: TWIN XL | D37: 39.0x80.0x18.0" | E37: Piping | F37: WXL | G37: Piping fabric - 100% Polyester satin fabric in silver color, Pantone Color - #14-4102TC | J37: 100% Polyester | K37: 70 | M37: Silver | N37: 180 | O37: 0.2 | P37: 6 | Q37: =IFERROR(O37*(1+P37/100)*VLOOKUP(B37,'1. Articles (SKUs)'!F:R,13,FALSE),"")
A38: FT4 | B38: GPMP46 | C38: FULL | D38: 54.0x75.0x18.0" | E38: Platform | F38: WXL | G38: 110gsm - 100% Polyester terry knitted fabric with 0.02mm TPUwhite coating | J38: 100% Polyester | K38: 110 | L38: TPU coated | M38: White | N38: 208 | O38: 1.42 | P38: 6 | Q38: =IFERROR(O38*(1+P38/100)*VLOOKUP(B38,'1. Articles (SKUs)'!F:R,13,FALSE),"")
A39: FT4 | B39: GPMP46 | C39: FULL | D39: 54.0x75.0x18.0" | E39: Skirt | F39: LXW | G39: 100% Polyester mesh knitted fabric | J39: 100% Polyester | K39: 70 | N39: 190 | O39: 1.66 | P39: 6 | Q39: =IFERROR(O39*(1+P39/100)*VLOOKUP(B39,'1. Articles (SKUs)'!F:R,13,FALSE),"")
A40: FT4 | B40: GPMP46 | C40: FULL | D40: 54.0x75.0x18.0" | E40: Piping | F40: WXL | G40: Piping fabric - 100% Polyester satin fabric in silver color, Pantone Color - #14-4102TC | J40: 100% Polyester | K40: 70 | M40: Silver | N40: 180 | O40: 0.21 | P40: 6 | Q40: =IFERROR(O40*(1+P40/100)*VLOOKUP(B40,'1. Articles (SKUs)'!F:R,13,FALSE),"")
...

Sheet 3. SKU Accessory Consumption
A1: tech_pack_code | B1: item_code | C1: size | D1: category | E1: item_name | F1: material | G1: size_spec | H1: placement | I1: variant | J1: consumption_per_unit | K1: unit | L1: wastage_percent | M1: total_required | N1: supplier
A2: FT2 | B2: GPFRIOMP33 | C2: TWIN | D2: Thread | E2: Polyester sewing thread | F2: 100% polyester spun | G2: TEX40 or 40/2 | H2: All seams | I2: Mattress protector | K2: meters | L2: 3 | M2: =IFERROR(J2*(1+IFERROR(L2,0)/100)*VLOOKUP(B2,'1. Articles (SKUs)'!F:R,13,FALSE),"")
A3: FT2 | B3: GPFRIOMP33 | C3: TWIN | D3: Elastic | E3: 1/8" H Elastic band | F3: Rubber/polyester | G3: 1/8" | H3: Around bottom edge | I3: Mattress protector | K3: meters | L3: 3 | M3: =IFERROR(J3*(1+IFERROR(L3,0)/100)*VLOOKUP(B3,'1. Articles (SKUs)'!F:R,13,FALSE),"")
A4: FT2 | B4: GPFRIOMP33 | C4: TWIN | D4: Law Tag | E4: Non woven label with coating | F4: 3M non woven material with white ground / black color font (INK CANNOT DISCOLORATION AND STAIN ON PRODUCT) | G4: 9.0cmX13.0cm | H4: Position of law tag label – Sewing at the middle of short si | I4: Law tag/Care label for mattress protector | J4: 1 | K4: pcs | L4: 2 | M4: =IFERROR(J4*(1+IFERROR(L4,0)/100)*VLOOKUP(B4,'1. Articles (SKUs)'!F:R,13,FALSE),"")
A5: FT2 | B5: GPFRIOMP33 | C5: TWIN | D5: Packaging | E5: Packaging type | F5: Color paper insert with vinyl PVC Bag with white bound seam & inside cardboard wrapped by product(Stiffener) | I5: Main | J5: 1 | K5: pcs | L5: 2 | M5: =IFERROR(J5*(1+IFERROR(L5,0)/100)*VLOOKUP(B5,'1. Articles (SKUs)'!F:R,13,FALSE),"")
A6: FT2 | B6: GPFRIOMP33 | C6: TWIN | D6: PVC Bag | E6: Bag material | F6: 12S (Thickness)- Transparent PVC Bag with 7S(Thickness) White PVC White Binding all around seam and 3# Nylon Coil White Zipper(No Hanger Loop on top) | I6: Mattress protector | J6: 1 | K6: pcs | L6: 2 | M6: =IFERROR(J6*(1+IFERROR(L6,0)/100)*VLOOKUP(B6,'1. Articles (SKUs)'!F:R,13,FALSE),"")
A7: FT2 | B7: GPFRIOMP33 | C7: TWIN | D7: Insert Card | E7: Color paper insert material | F7: Printed Insert quality - INSERT (“U” Shape) - Insert Material: 250g-300g White Card Paper with Coating both side | I7: Mattress protector | J7: 1 | K7: pcs | L7: 2 | M7: =IFERROR(J7*(1+IFERROR(L7,0)/100)*VLOOKUP(B7,'1. Articles (SKUs)'!F:R,13,FALSE),"")
A8: FT2 | B8: GPFRIOMP33 | C8: TWIN | D8: Stiffener | E8: Cardboard material(Stiffener) | F8: Packaging inside need to put a “U” 1 ply thickness(1 layers with 1 layer corrugated ) in White Cardboard to maintain the shape before putting into the box | I8: Mattress protector | J8: 1 | K8: pcs | L8: 2 | M8: =IFERROR(J8*(1+IFERROR(L8,0)/100)*VLOOKUP(B8,'1. Articles (SKUs)'!F:R,13,FALSE),"")
A9: FT2 | B9: GPFRIOMP38 | C9: TWIN XL | D9: Thread | E9: Polyester sewing thread | F9: 100% polyester spun | G9: TEX40 or 40/2 | H9: All seams | I9: Mattress protector | K9: meters | L9: 3 | M9: =IFERROR(J9*(1+IFERROR(L9,0)/100)*VLOOKUP(B9,'1. Articles (SKUs)'!F:R,13,FALSE),"")
A10: FT2 | B10: GPFRIOMP38 | C10: TWIN XL | D10: Elastic | E10: 1/8" H Elastic band | F10: Rubber/polyester | G10: 1/8" | H10: Around bottom edge | I10: Mattress protector | K10: meters | L10: 3 | M10: =IFERROR(J10*(1+IFERROR(L10,0)/100)*VLOOKUP(B10,'1. Articles (SKUs)'!F:R,13,FALSE),"")
A11: FT2 | B11: GPFRIOMP38 | C11: TWIN XL | D11: Law Tag | E11: Non woven label with coating | F11: 3M non woven material with white ground / black color font (INK CANNOT DISCOLORATION AND STAIN ON PRODUCT) | G11: 9.0cmX13.0cm | H11: Position of law tag label – Sewing at the middle of short si | I11: Law tag/Care label for mattress protector | J11: 1 | K11: pcs | L11: 2 | M11: =IFERROR(J11*(1+IFERROR(L11,0)/100)*VLOOKUP(B11,'1. Articles (SKUs)'!F:R,13,FALSE),"")
A12: FT2 | B12: GPFRIOMP38 | C12: TWIN XL | D12: Packaging | E12: Packaging type | F12: Color paper insert with vinyl PVC Bag with white bound seam & inside cardboard wrapped by product(Stiffener) | I12: Main | J12: 1 | K12: pcs | L12: 2 | M12: =IFERROR(J12*(1+IFERROR(L12,0)/100)*VLOOKUP(B12,'1. Articles (SKUs)'!F:R,13,FALSE),"")
A13: FT2 | B13: GPFRIOMP38 | C13: TWIN XL | D13: PVC Bag | E13: Bag material | F13: 12S (Thickness)- Transparent PVC Bag with 7S(Thickness) White PVC White Binding all around seam and 3# Nylon Coil White Zipper(No Hanger Loop on top) | I13: Mattress protector | J13: 1 | K13: pcs | L13: 2 | M13: =IFERROR(J13*(1+IFERROR(L13,0)/100)*VLOOKUP(B13,'1. Articles (SKUs)'!F:R,13,FALSE),"")
A14: FT2 | B14: GPFRIOMP38 | C14: TWIN XL | D14: Insert Card | E14: Color paper insert material | F14: Printed Insert quality - INSERT (“U” Shape) - Insert Material: 250g-300g White Card Paper with Coating both side | I14: Mattress protector | J14: 1 | K14: pcs | L14: 2 | M14: =IFERROR(J14*(1+IFERROR(L14,0)/100)*VLOOKUP(B14,'1. Articles (SKUs)'!F:R,13,FALSE),"")
A15: FT2 | B15: GPFRIOMP38 | C15: TWIN XL | D15: Stiffener | E15: Cardboard material(Stiffener) | F15: Packaging inside need to put a “U” 1 ply thickness(1 layers with 1 layer corrugated ) in White Cardboard to maintain the shape before putting into the box | I15: Mattress protector | J15: 1 | K15: pcs | L15: 2 | M15: =IFERROR(J15*(1+IFERROR(L15,0)/100)*VLOOKUP(B15,'1. Articles (SKUs)'!F:R,13,FALSE),"")
A16: FT2 | B16: GPFRIOMP46 | C16: FULL | D16: Thread | E16: Polyester sewing thread | F16: 100% polyester spun | G16: TEX40 or 40/2 | H16: All seams | I16: Mattress protector | K16: meters | L16: 3 | M16: =IFERROR(J16*(1+IFERROR(L16,0)/100)*VLOOKUP(B16,'1. Articles (SKUs)'!F:R,13,FALSE),"")
A17: FT2 | B17: GPFRIOMP46 | C17: FULL | D17: Elastic | E17: 1/8" H Elastic band | F17: Rubber/polyester | G17: 1/8" | H17: Around bottom edge | I17: Mattress protector | K17: meters | L17: 3 | M17: =IFERROR(J17*(1+IFERROR(L17,0)/100)*VLOOKUP(B17,'1. Articles (SKUs)'!F:R,13,FALSE),"")
A18: FT2 | B18: GPFRIOMP46 | C18: FULL | D18: Law Tag | E18: Non woven label with coating | F18: 3M non woven material with white ground / black color font (INK CANNOT DISCOLORATION AND STAIN ON PRODUCT) | G18: 9.0cmX13.0cm | H18: Position of law tag label – Sewing at the middle of short si | I18: Law tag/Care label for mattress protector | J18: 1 | K18: pcs | L18: 2 | M18: =IFERROR(J18*(1+IFERROR(L18,0)/100)*VLOOKUP(B18,'1. Articles (SKUs)'!F:R,13,FALSE),"")
A19: FT2 | B19: GPFRIOMP46 | C19: FULL | D19: Packaging | E19: Packaging type | F19: Color paper insert with vinyl PVC Bag with white bound seam & inside cardboard wrapped by product(Stiffener) | I19: Main | J19: 1 | K19: pcs | L19: 2 | M19: =IFERROR(J19*(1+IFERROR(L19,0)/100)*VLOOKUP(B19,'1. Articles (SKUs)'!F:R,13,FALSE),"")
A20: FT2 | B20: GPFRIOMP46 | C20: FULL | D20: PVC Bag | E20: Bag material | F20: 12S (Thickness)- Transparent PVC Bag with 7S(Thickness) White PVC White Binding all around seam and 3# Nylon Coil White Zipper(No Hanger Loop on top) | I20: Mattress protector | J20: 1 | K20: pcs | L20: 2 | M20: =IFERROR(J20*(1+IFERROR(L20,0)/100)*VLOOKUP(B20,'1. Articles (SKUs)'!F:R,13,FALSE),"")
A21: FT2 | B21: GPFRIOMP46 | C21: FULL | D21: Insert Card | E21: Color paper insert material | F21: Printed Insert quality - INSERT (“U” Shape) - Insert Material: 250g-300g White Card Paper with Coating both side | I21: Mattress protector | J21: 1 | K21: pcs | L21: 2 | M21: =IFERROR(J21*(1+IFERROR(L21,0)/100)*VLOOKUP(B21,'1. Articles (SKUs)'!F:R,13,FALSE),"")
A22: FT2 | B22: GPFRIOMP46 | C22: FULL | D22: Stiffener | E22: Cardboard material(Stiffener) | F22: Packaging inside need to put a “U” 1 ply thickness(1 layers with 1 layer corrugated ) in White Cardboard to maintain the shape before putting into the box | I22: Mattress protector | J22: 1 | K22: pcs | L22: 2 | M22: =IFERROR(J22*(1+IFERROR(L22,0)/100)*VLOOKUP(B22,'1. Articles (SKUs)'!F:R,13,FALSE),"")
A23: FT2 | B23: GPFRIOMP80 | C23: FULL XL | D23: Thread | E23: Polyester sewing thread | F23: 100% polyester spun | G23: TEX40 or 40/2 | H23: All seams | I23: Mattress protector | K23: meters | L23: 3 | M23: =IFERROR(J23*(1+IFERROR(L23,0)/100)*VLOOKUP(B23,'1. Articles (SKUs)'!F:R,13,FALSE),"")
A24: FT2 | B24: GPFRIOMP80 | C24: FULL XL | D24: Elastic | E24: 1/8" H Elastic band | F24: Rubber/polyester | G24: 1/8" | H24: Around bottom edge | I24: Mattress protector | K24: meters | L24: 3 | M24: =IFERROR(J24*(1+IFERROR(L24,0)/100)*VLOOKUP(B24,'1. Articles (SKUs)'!F:R,13,FALSE),"")
A25: FT2 | B25: GPFRIOMP80 | C25: FULL XL | D25: Law Tag | E25: Non woven label with coating | F25: 3M non woven material with white ground / black color font (INK CANNOT DISCOLORATION AND STAIN ON PRODUCT) | G25: 9.0cmX13.0cm | H25: Position of law tag label – Sewing at the middle of short si | I25: Law tag/Care label for mattress protector | J25: 1 | K25: pcs | L25: 2 | M25: =IFERROR(J25*(1+IFERROR(L25,0)/100)*VLOOKUP(B25,'1. Articles (SKUs)'!F:R,13,FALSE),"")
A26: FT2 | B26: GPFRIOMP80 | C26: FULL XL | D26: Packaging | E26: Packaging type | F26: Color paper insert with vinyl PVC Bag with white bound seam & inside cardboard wrapped by product(Stiffener) | I26: Main | J26: 1 | K26: pcs | L26: 2 | M26: =IFERROR(J26*(1+IFERROR(L26,0)/100)*VLOOKUP(B26,'1. Articles (SKUs)'!F:R,13,FALSE),"")
A27: FT2 | B27: GPFRIOMP80 | C27: FULL XL | D27: PVC Bag | E27: Bag material | F27: 12S (Thickness)- Transparent PVC Bag with 7S(Thickness) White PVC White Binding all around seam and 3# Nylon Coil White Zipper(No Hanger Loop on top) | I27: Mattress protector | J27: 1 | K27: pcs | L27: 2 | M27: =IFERROR(J27*(1+IFERROR(L27,0)/100)*VLOOKUP(B27,'1. Articles (SKUs)'!F:R,13,FALSE),"")
A28: FT2 | B28: GPFRIOMP80 | C28: FULL XL | D28: Insert Card | E28: Color paper insert material | F28: Printed Insert quality - INSERT (“U” Shape) - Insert Material: 250g-300g White Card Paper with Coating both side | I28: Mattress protector | J28: 1 | K28: pcs | L28: 2 | M28: =IFERROR(J28*(1+IFERROR(L28,0)/100)*VLOOKUP(B28,'1. Articles (SKUs)'!F:R,13,FALSE),"")
A29: FT2 | B29: GPFRIOMP80 | C29: FULL XL | D29: Stiffener | E29: Cardboard material(Stiffener) | F29: Packaging inside need to put a “U” 1 ply thickness(1 layers with 1 layer corrugated ) in White Cardboard to maintain the shape before putting into the box | I29: Mattress protector | J29: 1 | K29: pcs | L29: 2 | M29: =IFERROR(J29*(1+IFERROR(L29,0)/100)*VLOOKUP(B29,'1. Articles (SKUs)'!F:R,13,FALSE),"")
A30: FT2 | B30: GPFRIOMP50 | C30: QUEEN | D30: Thread | E30: Polyester sewing thread | F30: 100% polyester spun | G30: TEX40 or 40/2 | H30: All seams | I30: Mattress protector | K30: meters | L30: 3 | M30: =IFERROR(J30*(1+IFERROR(L30,0)/100)*VLOOKUP(B30,'1. Articles (SKUs)'!F:R,13,FALSE),"")
A31: FT2 | B31: GPFRIOMP50 | C31: QUEEN | D31: Elastic | E31: 1/8" H Elastic band | F31: Rubber/polyester | G31: 1/8" | H31: Around bottom edge | I31: Mattress protector | K31: meters | L31: 3 | M31: =IFERROR(J31*(1+IFERROR(L31,0)/100)*VLOOKUP(B31,'1. Articles (SKUs)'!F:R,13,FALSE),"")
A32: FT2 | B32: GPFRIOMP50 | C32: QUEEN | D32: Law Tag | E32: Non woven label with coating | F32: 3M non woven material with white ground / black color font (INK CANNOT DISCOLORATION AND STAIN ON PRODUCT) | G32: 9.0cmX13.0cm | H32: Position of law tag label – Sewing at the middle of short si | I32: Law tag/Care label for mattress protector | J32: 1 | K32: pcs | L32: 2 | M32: =IFERROR(J32*(1+IFERROR(L32,0)/100)*VLOOKUP(B32,'1. Articles (SKUs)'!F:R,13,FALSE),"")
A33: FT2 | B33: GPFRIOMP50 | C33: QUEEN | D33: Packaging | E33: Packaging type | F33: Color paper insert with vinyl PVC Bag with white bound seam & inside cardboard wrapped by product(Stiffener) | I33: Main | J33: 1 | K33: pcs | L33: 2 | M33: =IFERROR(J33*(1+IFERROR(L33,0)/100)*VLOOKUP(B33,'1. Articles (SKUs)'!F:R,13,FALSE),"")
A34: FT2 | B34: GPFRIOMP50 | C34: QUEEN | D34: PVC Bag | E34: Bag material | F34: 12S (Thickness)- Transparent PVC Bag with 7S(Thickness) White PVC White Binding all around seam and 3# Nylon Coil White Zipper(No Hanger Loop on top) | I34: Mattress protector | J34: 1 | K34: pcs | L34: 2 | M34: =IFERROR(J34*(1+IFERROR(L34,0)/100)*VLOOKUP(B34,'1. Articles (SKUs)'!F:R,13,FALSE),"")
A35: FT2 | B35: GPFRIOMP50 | C35: QUEEN | D35: Insert Card | E35: Color paper insert material | F35: Printed Insert quality - INSERT (“U” Shape) - Insert Material: 250g-300g White Card Paper with Coating both side | I35: Mattress protector | J35: 1 | K35: pcs | L35: 2 | M35: =IFERROR(J35*(1+IFERROR(L35,0)/100)*VLOOKUP(B35,'1. Articles (SKUs)'!F:R,13,FALSE),"")
A36: FT2 | B36: GPFRIOMP50 | C36: QUEEN | D36: Stiffener | E36: Cardboard material(Stiffener) | F36: Packaging inside need to put a “U” 1 ply thickness(1 layers with 1 layer corrugated ) in White Cardboard to maintain the shape before putting into the box | I36: Mattress protector | J36: 1 | K36: pcs | L36: 2 | M36: =IFERROR(J36*(1+IFERROR(L36,0)/100)*VLOOKUP(B36,'1. Articles (SKUs)'!F:R,13,FALSE),"")
A37: FT2 | B37: GPFRIOMP78 | C37: KING | D37: Thread | E37: Polyester sewing thread | F37: 100% polyester spun | G37: TEX40 or 40/2 | H37: All seams | I37: Mattress protector | K37: meters | L37: 3 | M37: =IFERROR(J37*(1+IFERROR(L37,0)/100)*VLOOKUP(B37,'1. Articles (SKUs)'!F:R,13,FALSE),"")
A38: FT2 | B38: GPFRIOMP78 | C38: KING | D38: Elastic | E38: 1/8" H Elastic band | F38: Rubber/polyester | G38: 1/8" | H38: Around bottom edge | I38: Mattress protector | K38: meters | L38: 3 | M38: =IFERROR(J38*(1+IFERROR(L38,0)/100)*VLOOKUP(B38,'1. Articles (SKUs)'!F:R,13,FALSE),"")
A39: FT2 | B39: GPFRIOMP78 | C39: KING | D39: Law Tag | E39: Non woven label with coating | F39: 3M non woven material with white ground / black color font (INK CANNOT DISCOLORATION AND STAIN ON PRODUCT) | G39: 9.0cmX13.0cm | H39: Position of law tag label – Sewing at the middle of short si | I39: Law tag/Care label for mattress protector | J39: 1 | K39: pcs | L39: 2 | M39: =IFERROR(J39*(1+IFERROR(L39,0)/100)*VLOOKUP(B39,'1. Articles (SKUs)'!F:R,13,FALSE),"")
A40: FT2 | B40: GPFRIOMP78 | C40: KING | D40: Packaging | E40: Packaging type | F40: Color paper insert with vinyl PVC Bag with white bound seam & inside cardboard wrapped by product(Stiffener) | I40: Main | J40: 1 | K40: pcs | L40: 2 | M40: =IFERROR(J40*(1+IFERROR(L40,0)/100)*VLOOKUP(B40,'1. Articles (SKUs)'!F:R,13,FALSE),"")
...

Sheet 4. Carton Master
A1: tech_pack_code | B1: size | C1: item_code | D1: units_per_carton | E1: carton_size_cm | F1: carton_length_cm | G1: carton_width_cm | H1: carton_height_cm | I1: cbm_per_carton | J1: weight_per_carton_kg
A2: FT2 | B2: TWIN | C2: GPFRIOMP33 | D2: 10 | E2: 56.0*29.0*27.0 | F2: 56 | G2: 29 | H2: 27 | I2: 0.0438
A3: FT2 | B3: SP CAL KING | C3: GPFRIOMP36 | D3: 10 | E3: 56.0*29.0*30.0 | F3: 56 | G3: 29 | H3: 30 | I3: 0.0487
A4: FT2 | B4: TWIN XL | C4: GPFRIOMP38 | D4: 10 | E4: 56.0*29.0*27.0 | F4: 56 | G4: 29 | H4: 27 | I4: 0.0438
A5: FT2 | B5: FULL | C5: GPFRIOMP46 | D5: 10 | E5: 56.0*29.0*27.0 | F5: 56 | G5: 29 | H5: 27 | I5: 0.0438
A6: FT2 | B6: QUEEN | C6: GPFRIOMP50 | D6: 10 | E6: 56.0*29.0*32.0 | F6: 56 | G6: 29 | H6: 32 | I6: 0.052
A7: FT2 | B7: SPLIT HEAD QUEEN | C7: GPFRIOMP52 | D7: 10 | E7: 56.0*29.0*32.0 | F7: 56 | G7: 29 | H7: 32 | I7: 0.052
A8: FT2 | B8: CAL KING | C8: GPFRIOMP72 | D8: 8 | E8: 56.0*29.0*30.0 | F8: 56 | G8: 29 | H8: 30 | I8: 0.0487
A9: FT2 | B9: KING | C9: GPFRIOMP78 | D9: 8 | E9: 56.0*29.0*30.0 | F9: 56 | G9: 29 | H9: 30 | I9: 0.0487
A10: FT2 | B10: SPLIT HEAD KING | C10: GPFRIOMP79 | D10: 8 | E10: 56.0*29.0*30.0 | F10: 56 | G10: 29 | H10: 30 | I10: 0.0487
A11: FT2 | B11: FULL XL | C11: GPFRIOMP80 | D11: 10 | E11: 56.0*29.0*27.0 | F11: 56 | G11: 29 | H11: 27 | I11: 0.0438
A12: FT2 | B12: KING | C12: GPFRIOPPK | D12: 24 | E12: 47.0*28.0*25.0 | F12: 47 | G12: 28 | H12: 25 | I12: 0.0329
A13: FT2 | B13: QUEEN | C13: GPFRIOPPQ | D13: 24 | E13: 47.0*28.0*25.0 | F13: 47 | G13: 28 | H13: 25 | I13: 0.0329
A14: FT4 | B14: T | C14: GPMP33 | D14: 10 | E14: 58.0*28.0*29.0 | F14: 58 | G14: 28 | H14: 29 | I14: 0.0471 | J14: 5.5
A15: FT4 | B15: SCK | C15: GPMP36 | D15: 10 | E15: 58.0*28.0*32.0 | F15: 58 | G15: 28 | H15: 32 | I15: 0.052 | J15: 6
A16: FT4 | B16: TXL | C16: GPMP38 | D16: 10 | E16: 58.0*28.0*29.0 | F16: 58 | G16: 28 | H16: 29 | I16: 0.0471 | J16: 5.7
A17: FT4 | B17: F | C17: GPMP46 | D17: 10 | E17: 58.0*28.0*35.0 | F17: 58 | G17: 28 | H17: 35 | I17: 0.0568 | J17: 6.8
A18: FT4 | B18: Q | C18: GPMP50 | D18: 10 | E18: 58.0*28.0*36.0 | F18: 58 | G18: 28 | H18: 36 | I18: 0.0585 | J18: 7.5
A19: FT4 | B19: SHQ | C19: GPMP52 | D19: 10 | E19: 58.0*28.0*36.0 | F19: 58 | G19: 28 | H19: 36 | I19: 0.0585 | J19: 7.5
A20: FT4 | B20: CK | C20: GPMP72 | D20: 8 | E20: 58.0*28.0*32.0 | F20: 58 | G20: 28 | H20: 32 | I20: 0.052 | J20: 7.3
A21: FT4 | B21: K | C21: GPMP78 | D21: 8 | E21: 58.0*28.0*32.0 | F21: 58 | G21: 28 | H21: 32 | I21: 0.052 | J21: 7.3
A22: FT4 | B22: SHK | C22: GPMP79 | D22: 8 | E22: 58.0*28.0*32.0 | F22: 58 | G22: 28 | H22: 32 | I22: 0.052 | J22: 7.3
A23: FT4 | B23: FXL | C23: GPMP80 | D23: 10 | E23: 58.0*28.0*35.0 | F23: 58 | G23: 28 | H23: 35 | I23: 0.0568 | J23: 7
A24: FT4 | B24: KING | C24: GPPPK | D24: 24 | E24: 47.0*28.0*25.0 | F24: 47 | G24: 28 | H24: 25 | I24: 0.0329
A25: FT4 | B25: QUEEN | C25: GPPPQ | D25: 24 | E25: 47.0*28.0*25.0 | F25: 47 | G25: 28 | H25: 25 | I25: 0.0329
A26: FT4 | B26: PPS | C26: GPPPS | D26: 24 | E26: 25.0*23.0*33.0 | F26: 25 | G26: 23 | H26: 33 | I26: 0.019 | J26: 4.3
A27: FT9 | B27: Twin Sleeper | C27: GPSE33 | D27: 10 | E27: 58.0*28.5*30.0 | F27: 58 | G27: 28.5 | H27: 30 | I27: 0.0496
A28: FT9 | B28: Full Sleeper | C28: GPSE46 | D28: 10 | E28: 58.0*28.5*38.0 | F28: 58 | G28: 28.5 | H28: 38 | I28: 0.0628 | J28: 9.2
A29: FT9 | B29: Queen Sleeper | C29: GPSE50 | D29: 10 | E29: 58.0*28.5*38.0 | F29: 58 | G29: 28.5 | H29: 38 | I29: 0.0628 | J29: 10
A30: FT9 | B30: T | C30: GPTE33 | D30: 10 | E30: 58.0*28.5*34.0 | F30: 58 | G30: 28.5 | H30: 34 | I30: 0.0562 | J30: 8
A31: FT9 | B31: SCK | C31: GPTE36 | D31: 10 | E31: 58.0*28.5*34.0 | F31: 58 | G31: 28.5 | H31: 34 | I31: 0.0562 | J31: 8.5
A32: FT9 | B32: TXL | C32: GPTE38 | D32: 10 | E32: 58.0*28.5*34.0 | F32: 58 | G32: 28.5 | H32: 34 | I32: 0.0562 | J32: 8.3
A33: FT9 | B33: F | C33: GPTE46 | D33: 10 | E33: 58.0*28.5*44.0 | F33: 58 | G33: 28.5 | H33: 44 | I33: 0.0727 | J33: 9.7
A34: FT9 | B34: Q | C34: GPTE50 | D34: 10 | E34: 58.0*28.5*49.0 | F34: 58 | G34: 28.5 | H34: 49 | I34: 0.081 | J34: 10.5
A35: FT9 | B35: Split Head Queen | C35: GPTE52 | D35: 10 | E35: 58.0*28.5*49.0 | F35: 58 | G35: 28.5 | H35: 49 | I35: 0.081 | J35: 10.5
A36: FT9 | B36: CK | C36: GPTE72 | D36: 8 | E36: 58.0*28.5*43.0 | F36: 58 | G36: 28.5 | H36: 43 | I36: 0.0711 | J36: 11.1
A37: FT9 | B37: K | C37: GPTE78 | D37: 8 | E37: 58.0*28.5*43.0 | F37: 58 | G37: 28.5 | H37: 43 | I37: 0.0711 | J37: 11.1
A38: FT9 | B38: Split Head King | C38: GPTE79 | D38: 8 | E38: 58.0*28.5*43.0 | F38: 58 | G38: 28.5 | H38: 43 | I38: 0.0711 | J38: 11.1
A39: FT9 | B39: FXL | C39: GPTE80 | D39: 10 | E39: 58.0*28.5*44.0 | F39: 58 | G39: 28.5 | H39: 44 | I39: 0.0727 | J39: 10

Sheet 5. Price List
A1: item_code | B1: item_description | C1: price_usd | D1: currency | E1: effective_from | F1: effective_to | G1: pieces_per_carton | H1: carton_length_cm | I1: carton_width_cm | J1: carton_height_cm | K1: cbm_per_carton | L1: is_active | M1: notes
A2: GPFRIOMP33 | B2: Cooling Waterproof mattress protector — TWIN White | C2: 5.31 | D2: USD | E2: 2026-04-21 | G2: 10 | H2: 56 | I2: 29 | J2: 27 | K2: 0.0438 | L2: TRUE
A3: GPFRIOMP38 | B3: Cooling Waterproof mattress protector — TWIN XL White | C3: 5.36 | D3: USD | E3: 2026-04-21 | G3: 10 | H3: 56 | I3: 29 | J3: 27 | K3: 0.0438 | L3: TRUE
A4: GPFRIOMP46 | B4: Cooling Waterproof mattress protector — FULL White | C4: 6.79 | D4: USD | E4: 2026-04-21 | G4: 10 | H4: 56 | I4: 29 | J4: 27 | K4: 0.0438 | L4: TRUE
A5: GPFRIOMP80 | B5: Cooling Waterproof mattress protector — FULL XL White | D5: USD | G5: 10 | H5: 56 | I5: 29 | J5: 27 | K5: 0.0438 | L5: FALSE
A6: GPFRIOMP50 | B6: Cooling Waterproof mattress protector — QUEEN White | C6: 8.08 | D6: USD | E6: 2026-04-21 | G6: 10 | H6: 56 | I6: 29 | J6: 32 | K6: 0.052 | L6: TRUE
A7: GPFRIOMP78 | B7: Cooling Waterproof mattress protector — KING White | C7: 9.75 | D7: USD | E7: 2026-04-21 | G7: 8 | H7: 56 | I7: 29 | J7: 30 | K7: 0.0487 | L7: TRUE
A8: GPFRIOMP72 | B8: Cooling Waterproof mattress protector — CAL KING White | C8: 9.75 | D8: USD | E8: 2026-04-21 | G8: 8 | H8: 56 | I8: 29 | J8: 30 | K8: 0.0487 | L8: TRUE
A9: GPFRIOMP36 | B9: Cooling Waterproof mattress protector — SPLIT CAL KING White | D9: USD | L9: FALSE
A10: GPFRIOMP52 | B10: Cooling Waterproof mattress protector — SPLIT HEAD QUEEN White | C10: 9.14 | D10: USD | E10: 2026-04-21 | G10: 10 | H10: 56 | I10: 29 | J10: 32 | K10: 0.052 | L10: TRUE
A11: GPFRIOMP79 | B11: Cooling Waterproof mattress protector — SPLIT HEAD KING White | C11: 10.81 | D11: USD | E11: 2026-04-21 | G11: 8 | H11: 56 | I11: 29 | J11: 30 | K11: 0.0487 | L11: TRUE
A12: GPMP33 | B12: Poly terry Waterproof mattress protector — TWIN White | C12: 3.35 | D12: USD | E12: 2026-04-21 | L12: TRUE
A13: GPMP38 | B13: Poly terry Waterproof mattress protector — TWIN XL White | C13: 3.35 | D13: USD | E13: 2026-04-21 | L13: TRUE
A14: GPMP46 | B14: Poly terry Waterproof mattress protector — FULL White | C14: 4.11 | D14: USD | E14: 2026-04-21 | L14: TRUE
A15: GPMP80 | B15: Poly terry Waterproof mattress protector — FULL XL White | D15: USD | L15: FALSE
A16: GPMP50 | B16: Poly terry Waterproof mattress protector — QUEEN White | C16: 4.59 | D16: USD | E16: 2026-04-21 | L16: TRUE
A17: GPMP78 | B17: Poly terry Waterproof mattress protector — KING White | C17: 5.74 | D17: USD | E17: 2026-04-21 | L17: TRUE
A18: GPMP72 | B18: Poly terry Waterproof mattress protector — CAL KING White | C18: 5.74 | D18: USD | E18: 2026-04-21 | L18: TRUE
A19: GPMP36 | B19: Poly terry Waterproof mattress protector — SPLIT CAL KING White | D19: USD | L19: FALSE
A20: GPMP52 | B20: Poly terry Waterproof mattress protector — SPLIT HEAD QUEEN White | C20: 5.31 | D20: USD | E20: 2026-04-21 | L20: TRUE
A21: GPMP79 | B21: Poly terry Waterproof mattress protector — SPLIT HEAD KING White | C21: 6.46 | D21: USD | E21: 2026-04-21 | L21: TRUE
A22: GPTE33 | B22: Poly terry waterproof total encasement protector — TWIN White | C22: 6.03 | D22: USD | E22: 2026-04-21 | L22: TRUE
A23: GPTE38 | B23: Poly terry waterproof total encasement protector — TWIN XL White | C23: 6.13 | D23: USD | E23: 2026-04-21 | L23: TRUE
A24: GPTE46 | B24: Poly terry waterproof total encasement protector — FULL White | C24: 7.47 | D24: USD | E24: 2026-04-21 | L24: TRUE
A25: GPTE80 | B25: Poly terry waterproof total encasement protector — FULL XL White | D25: USD | L25: FALSE
A26: GPTE50 | B26: Poly terry waterproof total encasement protector — QUEEN White | C26: 8.71 | D26: USD | E26: 2026-04-21 | L26: TRUE
A27: GPTE78 | B27: Poly terry waterproof total encasement protector — KING White | C27: 10.62 | D27: USD | E27: 2026-04-21 | L27: TRUE
A28: GPTE72 | B28: Poly terry waterproof total encasement protector — CAL KING White | C28: 10.62 | D28: USD | E28: 2026-04-21 | L28: TRUE
A29: GPTE36 | B29: Poly terry waterproof total encasement protector — SP CAL KING White | D29: USD | L29: FALSE
A30: GPTE52 | B30: Poly terry waterproof total encasement protector — SPLIT HEAD QUEEN White | C30: 11.44 | D30: USD | E30: 2026-04-21 | G30: 10 | H30: 58 | I30: 28.5 | J30: 49 | K30: 0.081 | L30: TRUE
A31: GPTE79 | B31: Poly terry waterproof total encasement protector — SPLIT HEAD KING White | C31: 12.73 | D31: USD | E31: 2026-04-21 | G31: 8 | H31: 58 | I31: 28.5 | J31: 43 | K31: 0.0711 | L31: TRUE
A32: GPSE33 | B32: Poly terry waterproof total encasement protector — SLEEPER - TWIN White | C32: 6.51 | D32: USD | E32: 2026-04-21 | L32: TRUE
A33: GPSE46 | B33: Poly terry waterproof total encasement protector — SLEEPER - FULL White | C33: 7.55 | D33: USD | E33: 2026-04-21 | L33: TRUE
A34: GPSE50 | B34: Poly terry waterproof total encasement protector — SLEEPER - QUEEN White | C34: 8.52 | D34: USD | E34: 2026-04-21 | L34: TRUE
A35: GPPPQ | B35: Pillow Protector — QUEEN White | D35: USD | G35: 24 | H35: 47 | I35: 28 | J35: 25 | K35: 0.0329 | L35: FALSE | M35: Fill price before importing PO
A36: GPPPK | B36: Pillow Protector — KING White | D36: USD | G36: 24 | H36: 47 | I36: 28 | J36: 25 | K36: 0.0329 | L36: FALSE | M36: Fill price before importing PO
A37: GPFRIOPPQ | B37: Pillow Protector — QUEEN White | D37: USD | G37: 24 | H37: 47 | I37: 28 | J37: 25 | K37: 0.0329 | L37: FALSE | M37: Fill price before importing PO
A38: GPFRIOPPK | B38: Pillow Protector — KING White | D38: USD | G38: 24 | H38: 47 | I38: 28 | J38: 25 | K38: 0.0329 | L38: FALSE | M38: Fill price before importing PO

Sheet 6. Suppliers
A1: name | B1: code | C1: category | D1: supplier_type | E1: contact_person | F1: email | G1: phone | H1: whatsapp | I1: city | J1: country | K1: payment_terms | L1: currency | M1: lead_time_days | N1: rating | O1: notes
A2: ABC Textiles Ltd | B2: SUP-001 | C2: Fabric | D2: Mill | E2: John Doe | F2: john@abc.com | G2: +92 21 1234 5678 | H2: +92 300 1234567 | I2: Karachi | J2: Pakistan | K2: 30 days net | L2: USD | M2: 30 | N2: 4.5

Sheet 7. Seasons
A1: name | B1: start_date | C1: end_date | D1: notes | E1: status
A2: SS26 | B2: 2026-01-01 | C2: 2026-06-30 | D2: Spring/Summer 2026 | E2: active

Sheet 8. Production Lines
A1: name | B1: line_type | C1: daily_capacity | D1: operator_count | E1: is_active | F1: notes
A2: Line 1 | B2: stitching | C2: 500 | D2: 15 | E2: TRUE | F2: Main stitching line
